[2023-04-28T15:07:31.507+0000] {taskinstance.py:1083} INFO - Dependencies all met for <TaskInstance: stock_analyzer.stocks_data_validation manual__2023-04-28T15:06:47.714566+00:00 [queued]>
[2023-04-28T15:07:31.524+0000] {taskinstance.py:1083} INFO - Dependencies all met for <TaskInstance: stock_analyzer.stocks_data_validation manual__2023-04-28T15:06:47.714566+00:00 [queued]>
[2023-04-28T15:07:31.525+0000] {taskinstance.py:1279} INFO - 
--------------------------------------------------------------------------------
[2023-04-28T15:07:31.525+0000] {taskinstance.py:1280} INFO - Starting attempt 1 of 1
[2023-04-28T15:07:31.526+0000] {taskinstance.py:1281} INFO - 
--------------------------------------------------------------------------------
[2023-04-28T15:07:31.541+0000] {taskinstance.py:1300} INFO - Executing <Task(GreatExpectationsOperator): stocks_data_validation> on 2023-04-28 15:06:47.714566+00:00
[2023-04-28T15:07:31.555+0000] {standard_task_runner.py:55} INFO - Started process 1519 to run task
[2023-04-28T15:07:31.560+0000] {standard_task_runner.py:82} INFO - Running: ['***', 'tasks', 'run', 'stock_analyzer', 'stocks_data_validation', 'manual__2023-04-28T15:06:47.714566+00:00', '--job-id', '18', '--raw', '--subdir', 'DAGS_FOLDER/main.py', '--cfg-path', '/tmp/tmpku2el6ou']
[2023-04-28T15:07:31.561+0000] {standard_task_runner.py:83} INFO - Job 18: Subtask stocks_data_validation
[2023-04-28T15:07:31.659+0000] {task_command.py:388} INFO - Running <TaskInstance: stock_analyzer.stocks_data_validation manual__2023-04-28T15:06:47.714566+00:00 [running]> on host e48c557aa0b5
[2023-04-28T15:07:31.826+0000] {taskinstance.py:1509} INFO - Exporting the following env vars:
AIRFLOW_CTX_DAG_OWNER=***
AIRFLOW_CTX_DAG_ID=stock_analyzer
AIRFLOW_CTX_TASK_ID=stocks_data_validation
AIRFLOW_CTX_EXECUTION_DATE=2023-04-28T15:06:47.714566+00:00
AIRFLOW_CTX_TRY_NUMBER=1
AIRFLOW_CTX_DAG_RUN_ID=manual__2023-04-28T15:06:47.714566+00:00
[2023-04-28T15:07:31.832+0000] {great_expectations.py:143} INFO - Running validation with Great Expectations...
[2023-04-28T15:07:32.333+0000] {validator.py:1428} INFO - 	26 expectation(s) included in expectation_suite.
[2023-04-28T15:07:33.885+0000] {logging_mixin.py:137} WARNING - Calculating Metrics:   0%|          | 0/87 [00:00<?, ?it/s]
[2023-04-28T15:07:33.886+0000] {logging_mixin.py:137} WARNING - Calculating Metrics:   0%|          | 0/87 [00:00<?, ?it/s]
[2023-04-28T15:07:33.894+0000] {logging_mixin.py:137} WARNING - Calculating Metrics:   2%|2         | 2/87 [00:00<00:00, 243.94it/s]
[2023-04-28T15:07:34.022+0000] {logging_mixin.py:137} WARNING - Calculating Metrics:   2%|2         | 2/87 [00:00<00:05, 14.82it/s] 
[2023-04-28T15:07:34.022+0000] {logging_mixin.py:137} WARNING - Calculating Metrics:   2%|2         | 2/87 [00:00<00:05, 14.82it/s]
[2023-04-28T15:07:34.023+0000] {logging_mixin.py:137} WARNING - Calculating Metrics:   3%|3         | 3/87 [00:00<00:05, 14.82it/s]
[2023-04-28T15:07:34.223+0000] {logging_mixin.py:137} WARNING - Calculating Metrics:   3%|3         | 3/87 [00:00<00:05, 14.82it/s]
[2023-04-28T15:07:34.298+0000] {logging_mixin.py:137} WARNING - Calculating Metrics:  32%|###2      | 28/87 [00:00<00:00, 73.64it/s]
[2023-04-28T15:07:34.299+0000] {logging_mixin.py:137} WARNING - Calculating Metrics:  32%|###2      | 28/87 [00:00<00:00, 73.64it/s]
[2023-04-28T15:07:34.415+0000] {logging_mixin.py:137} WARNING - Calculating Metrics:  32%|###2      | 28/87 [00:00<00:00, 73.64it/s]
[2023-04-28T15:07:34.500+0000] {logging_mixin.py:137} WARNING - Calculating Metrics:  90%|########9 | 78/87 [00:00<00:00, 149.44it/s]
[2023-04-28T15:07:34.501+0000] {logging_mixin.py:137} WARNING - Calculating Metrics:  90%|########9 | 78/87 [00:00<00:00, 149.44it/s]
[2023-04-28T15:07:34.569+0000] {logging_mixin.py:137} WARNING - Calculating Metrics:  90%|########9 | 78/87 [00:00<00:00, 149.44it/s]
[2023-04-28T15:07:34.586+0000] {logging_mixin.py:137} WARNING - Calculating Metrics: 100%|##########| 87/87 [00:00<00:00, 149.44it/s]
[2023-04-28T15:07:34.728+0000] {logging_mixin.py:137} WARNING - Calculating Metrics: 100%|##########| 87/87 [00:00<00:00, 149.44it/s]
[2023-04-28T15:07:34.728+0000] {logging_mixin.py:137} WARNING - Calculating Metrics: 100%|##########| 87/87 [00:00<00:00, 149.44it/s]
[2023-04-28T15:07:34.728+0000] {logging_mixin.py:137} WARNING - Calculating Metrics: 100%|##########| 87/87 [00:00<00:00, 103.19it/s]
[2023-04-28T15:08:25.441+0000] {base_job.py:243} ERROR - LocalTaskJob heartbeat got an exception
Traceback (most recent call last):
  File "/home/airflow/.local/lib/python3.7/site-packages/sqlalchemy/engine/base.py", line 3141, in _wrap_pool_connect
    return fn()
  File "/home/airflow/.local/lib/python3.7/site-packages/sqlalchemy/pool/base.py", line 301, in connect
    return _ConnectionFairy._checkout(self)
  File "/home/airflow/.local/lib/python3.7/site-packages/sqlalchemy/pool/base.py", line 755, in _checkout
    fairy = _ConnectionRecord.checkout(pool)
  File "/home/airflow/.local/lib/python3.7/site-packages/sqlalchemy/pool/base.py", line 419, in checkout
    rec = pool._do_get()
  File "/home/airflow/.local/lib/python3.7/site-packages/sqlalchemy/pool/impl.py", line 259, in _do_get
    return self._create_connection()
  File "/home/airflow/.local/lib/python3.7/site-packages/sqlalchemy/pool/base.py", line 247, in _create_connection
    return _ConnectionRecord(self)
  File "/home/airflow/.local/lib/python3.7/site-packages/sqlalchemy/pool/base.py", line 362, in __init__
    self.__connect(first_connect_check=True)
  File "/home/airflow/.local/lib/python3.7/site-packages/sqlalchemy/pool/base.py", line 605, in __connect
    pool.logger.debug("Error on connect(): %s", e)
  File "/home/airflow/.local/lib/python3.7/site-packages/sqlalchemy/util/langhelpers.py", line 72, in __exit__
    with_traceback=exc_tb,
  File "/home/airflow/.local/lib/python3.7/site-packages/sqlalchemy/util/compat.py", line 211, in raise_
    raise exception
  File "/home/airflow/.local/lib/python3.7/site-packages/sqlalchemy/pool/base.py", line 599, in __connect
    connection = pool._invoke_creator(self)
  File "/home/airflow/.local/lib/python3.7/site-packages/sqlalchemy/engine/create.py", line 578, in connect
    return dialect.connect(*cargs, **cparams)
  File "/home/airflow/.local/lib/python3.7/site-packages/sqlalchemy/engine/default.py", line 583, in connect
    return self.dbapi.connect(*cargs, **cparams)
  File "/home/airflow/.local/lib/python3.7/site-packages/psycopg2/__init__.py", line 122, in connect
    conn = _connect(dsn, connection_factory=connection_factory, **kwasync)
psycopg2.OperationalError: could not translate host name "postgres" to address: Temporary failure in name resolution


The above exception was the direct cause of the following exception:

Traceback (most recent call last):
  File "/home/airflow/.local/lib/python3.7/site-packages/airflow/jobs/base_job.py", line 215, in heartbeat
    session.merge(self)
  File "/home/airflow/.local/lib/python3.7/site-packages/sqlalchemy/orm/session.py", line 2877, in merge
    _resolve_conflict_map=_resolve_conflict_map,
  File "/home/airflow/.local/lib/python3.7/site-packages/sqlalchemy/orm/session.py", line 2950, in _merge
    merged = self.get(mapper.class_, key[1], identity_token=key[2])
  File "/home/airflow/.local/lib/python3.7/site-packages/sqlalchemy/orm/session.py", line 2702, in get
    identity_token=identity_token,
  File "/home/airflow/.local/lib/python3.7/site-packages/sqlalchemy/orm/session.py", line 2800, in _get_impl
    load_options=load_options,
  File "/home/airflow/.local/lib/python3.7/site-packages/sqlalchemy/orm/loading.py", line 535, in load_on_pk_identity
    bind_arguments=bind_arguments,
  File "/home/airflow/.local/lib/python3.7/site-packages/sqlalchemy/orm/session.py", line 1669, in execute
    conn = self._connection_for_bind(bind, close_with_result=True)
  File "/home/airflow/.local/lib/python3.7/site-packages/sqlalchemy/orm/session.py", line 1520, in _connection_for_bind
    engine, execution_options
  File "/home/airflow/.local/lib/python3.7/site-packages/sqlalchemy/orm/session.py", line 747, in _connection_for_bind
    conn = bind.connect()
  File "/home/airflow/.local/lib/python3.7/site-packages/sqlalchemy/engine/base.py", line 3095, in connect
    return self._connection_cls(self, close_with_result=close_with_result)
  File "/home/airflow/.local/lib/python3.7/site-packages/sqlalchemy/engine/base.py", line 91, in __init__
    else engine.raw_connection()
  File "/home/airflow/.local/lib/python3.7/site-packages/sqlalchemy/engine/base.py", line 3174, in raw_connection
    return self._wrap_pool_connect(self.pool.connect, _connection)
  File "/home/airflow/.local/lib/python3.7/site-packages/sqlalchemy/engine/base.py", line 3145, in _wrap_pool_connect
    e, dialect, self
  File "/home/airflow/.local/lib/python3.7/site-packages/sqlalchemy/engine/base.py", line 2004, in _handle_dbapi_exception_noconnection
    sqlalchemy_exception, with_traceback=exc_info[2], from_=e
  File "/home/airflow/.local/lib/python3.7/site-packages/sqlalchemy/util/compat.py", line 211, in raise_
    raise exception
  File "/home/airflow/.local/lib/python3.7/site-packages/sqlalchemy/engine/base.py", line 3141, in _wrap_pool_connect
    return fn()
  File "/home/airflow/.local/lib/python3.7/site-packages/sqlalchemy/pool/base.py", line 301, in connect
    return _ConnectionFairy._checkout(self)
  File "/home/airflow/.local/lib/python3.7/site-packages/sqlalchemy/pool/base.py", line 755, in _checkout
    fairy = _ConnectionRecord.checkout(pool)
  File "/home/airflow/.local/lib/python3.7/site-packages/sqlalchemy/pool/base.py", line 419, in checkout
    rec = pool._do_get()
  File "/home/airflow/.local/lib/python3.7/site-packages/sqlalchemy/pool/impl.py", line 259, in _do_get
    return self._create_connection()
  File "/home/airflow/.local/lib/python3.7/site-packages/sqlalchemy/pool/base.py", line 247, in _create_connection
    return _ConnectionRecord(self)
  File "/home/airflow/.local/lib/python3.7/site-packages/sqlalchemy/pool/base.py", line 362, in __init__
    self.__connect(first_connect_check=True)
  File "/home/airflow/.local/lib/python3.7/site-packages/sqlalchemy/pool/base.py", line 605, in __connect
    pool.logger.debug("Error on connect(): %s", e)
  File "/home/airflow/.local/lib/python3.7/site-packages/sqlalchemy/util/langhelpers.py", line 72, in __exit__
    with_traceback=exc_tb,
  File "/home/airflow/.local/lib/python3.7/site-packages/sqlalchemy/util/compat.py", line 211, in raise_
    raise exception
  File "/home/airflow/.local/lib/python3.7/site-packages/sqlalchemy/pool/base.py", line 599, in __connect
    connection = pool._invoke_creator(self)
  File "/home/airflow/.local/lib/python3.7/site-packages/sqlalchemy/engine/create.py", line 578, in connect
    return dialect.connect(*cargs, **cparams)
  File "/home/airflow/.local/lib/python3.7/site-packages/sqlalchemy/engine/default.py", line 583, in connect
    return self.dbapi.connect(*cargs, **cparams)
  File "/home/airflow/.local/lib/python3.7/site-packages/psycopg2/__init__.py", line 122, in connect
    conn = _connect(dsn, connection_factory=connection_factory, **kwasync)
sqlalchemy.exc.OperationalError: (psycopg2.OperationalError) could not translate host name "postgres" to address: Temporary failure in name resolution

(Background on this error at: http://sqlalche.me/e/14/e3q8)
[2023-04-28T15:09:18.378+0000] {local_task_job.py:208} INFO - Task exited with return code Negsignal.SIGKILL
[2023-04-28T15:09:20.551+0000] {taskinstance.py:2578} INFO - 0 downstream tasks scheduled from follow-on schedule check
