[2023-04-26T16:43:12.994+0000] {processor.py:153} INFO - Started process (PID=231) to work on /opt/airflow/dags/noaa.py
[2023-04-26T16:43:13.072+0000] {processor.py:743} INFO - Processing file /opt/airflow/dags/noaa.py for tasks to queue
[2023-04-26T16:43:13.080+0000] {logging_mixin.py:137} INFO - [2023-04-26T16:43:13.079+0000] {dagbag.py:538} INFO - Filling up the DagBag from /opt/airflow/dags/noaa.py
[2023-04-26T16:43:54.067+0000] {logging_mixin.py:137} INFO - [2023-04-26T16:43:50.194+0000] {timeout.py:68} ERROR - Process timed out, PID: 231
[2023-04-26T16:43:55.136+0000] {logging_mixin.py:137} INFO - [2023-04-26T16:43:54.142+0000] {dagbag.py:343} ERROR - Failed to import: /opt/airflow/dags/noaa.py
Traceback (most recent call last):
  File "/home/airflow/.local/lib/python3.7/site-packages/airflow/models/dagbag.py", line 339, in parse
    loader.exec_module(new_module)
  File "<frozen importlib._bootstrap_external>", line 728, in exec_module
  File "<frozen importlib._bootstrap>", line 219, in _call_with_frames_removed
  File "/opt/airflow/dags/noaa.py", line 8, in <module>
    import pandas as pd
  File "/home/airflow/.local/lib/python3.7/site-packages/pandas/__init__.py", line 50, in <module>
    from pandas.core.api import (
  File "/home/airflow/.local/lib/python3.7/site-packages/pandas/core/api.py", line 29, in <module>
    from pandas.core.arrays import Categorical
  File "/home/airflow/.local/lib/python3.7/site-packages/pandas/core/arrays/__init__.py", line 20, in <module>
    from pandas.core.arrays.string_arrow import ArrowStringArray
  File "/home/airflow/.local/lib/python3.7/site-packages/pandas/core/arrays/string_arrow.py", line 65, in <module>
    import pyarrow.compute as pc
  File "/home/airflow/.local/lib/python3.7/site-packages/pyarrow/compute.py", line 18, in <module>
    from pyarrow._compute import (  # noqa
  File "pyarrow/_compute.pyx", line 1349, in init pyarrow._compute
  File "pyarrow/_compute.pyx", line 799, in pyarrow._compute._min_count_doc
  File "/home/airflow/.local/lib/python3.7/site-packages/airflow/utils/timeout.py", line 69, in handle_timeout
    raise AirflowTaskTimeout(self.error_message)
airflow.exceptions.AirflowTaskTimeout: DagBag import timeout for /opt/airflow/dags/noaa.py after 30.0s.
Please take a look at these docs to improve your DAG import time:
* https://airflow.apache.org/docs/apache-airflow/2.5.1/best-practices.html#top-level-python-code
* https://airflow.apache.org/docs/apache-airflow/2.5.1/best-practices.html#reducing-dag-complexity, PID: 231
[2023-04-26T16:43:55.912+0000] {processor.py:755} WARNING - No viable dags retrieved from /opt/airflow/dags/noaa.py
[2023-04-26T22:42:05.431+0000] {processor.py:153} INFO - Started process (PID=86) to work on /opt/airflow/dags/noaa.py
[2023-04-26T22:42:43.421+0000] {processor.py:743} INFO - Processing file /opt/airflow/dags/noaa.py for tasks to queue
[2023-04-26T22:42:43.673+0000] {logging_mixin.py:137} INFO - [2023-04-26T22:42:43.643+0000] {dagbag.py:538} INFO - Filling up the DagBag from /opt/airflow/dags/noaa.py
[2023-04-26T22:42:47.082+0000] {logging_mixin.py:137} INFO - [2023-04-26T22:42:44.050+0000] {dagbag.py:343} ERROR - Failed to import: /opt/airflow/dags/noaa.py
Traceback (most recent call last):
  File "/home/airflow/.local/lib/python3.7/site-packages/airflow/models/dagbag.py", line 339, in parse
    loader.exec_module(new_module)
  File "<frozen importlib._bootstrap_external>", line 724, in exec_module
  File "<frozen importlib._bootstrap_external>", line 860, in get_code
  File "<frozen importlib._bootstrap_external>", line 791, in source_to_code
  File "<frozen importlib._bootstrap>", line 219, in _call_with_frames_removed
  File "/opt/airflow/dags/noaa.py", line 70
    ge_data_context_root_dir_with_checkpoint_name_pass = GreatExpectationsOperator(
    ^
IndentationError: unexpected indent
[2023-04-26T22:42:47.170+0000] {processor.py:755} WARNING - No viable dags retrieved from /opt/airflow/dags/noaa.py
[2023-04-26T22:42:56.908+0000] {processor.py:175} INFO - Processing /opt/airflow/dags/noaa.py took 36.740 seconds
[2023-04-26T23:00:46.897+0000] {processor.py:153} INFO - Started process (PID=136) to work on /opt/airflow/dags/noaa.py
[2023-04-26T23:00:46.988+0000] {processor.py:743} INFO - Processing file /opt/airflow/dags/noaa.py for tasks to queue
[2023-04-26T23:00:47.360+0000] {logging_mixin.py:137} INFO - [2023-04-26T23:00:47.239+0000] {dagbag.py:538} INFO - Filling up the DagBag from /opt/airflow/dags/noaa.py
[2023-04-26T23:00:49.343+0000] {logging_mixin.py:137} INFO - [2023-04-26T23:00:48.380+0000] {dagbag.py:343} ERROR - Failed to import: /opt/airflow/dags/noaa.py
Traceback (most recent call last):
  File "/home/airflow/.local/lib/python3.7/site-packages/airflow/models/dagbag.py", line 339, in parse
    loader.exec_module(new_module)
  File "<frozen importlib._bootstrap_external>", line 724, in exec_module
  File "<frozen importlib._bootstrap_external>", line 860, in get_code
  File "<frozen importlib._bootstrap_external>", line 791, in source_to_code
  File "<frozen importlib._bootstrap>", line 219, in _call_with_frames_removed
  File "/opt/airflow/dags/noaa.py", line 70
    ge_data_context_root_dir_with_checkpoint_name_pass = GreatExpectationsOperator(
    ^
IndentationError: unexpected indent
[2023-04-26T23:00:49.850+0000] {processor.py:755} WARNING - No viable dags retrieved from /opt/airflow/dags/noaa.py
[2023-04-26T23:07:29.730+0000] {processor.py:153} INFO - Started process (PID=191) to work on /opt/airflow/dags/noaa.py
[2023-04-26T23:07:29.842+0000] {processor.py:743} INFO - Processing file /opt/airflow/dags/noaa.py for tasks to queue
[2023-04-26T23:07:29.848+0000] {logging_mixin.py:137} INFO - [2023-04-26T23:07:29.847+0000] {dagbag.py:538} INFO - Filling up the DagBag from /opt/airflow/dags/noaa.py
[2023-04-26T23:07:44.086+0000] {logging_mixin.py:137} INFO - [2023-04-26T23:07:30.345+0000] {dagbag.py:343} ERROR - Failed to import: /opt/airflow/dags/noaa.py
Traceback (most recent call last):
  File "/home/airflow/.local/lib/python3.7/site-packages/airflow/models/dagbag.py", line 339, in parse
    loader.exec_module(new_module)
  File "<frozen importlib._bootstrap_external>", line 724, in exec_module
  File "<frozen importlib._bootstrap_external>", line 860, in get_code
  File "<frozen importlib._bootstrap_external>", line 791, in source_to_code
  File "<frozen importlib._bootstrap>", line 219, in _call_with_frames_removed
  File "/opt/airflow/dags/noaa.py", line 70
    ge_data_context_root_dir_with_checkpoint_name_pass = GreatExpectationsOperator(
    ^
IndentationError: unexpected indent
[2023-04-26T23:07:47.203+0000] {processor.py:755} WARNING - No viable dags retrieved from /opt/airflow/dags/noaa.py
[2023-04-26T23:08:09.731+0000] {processor.py:178} ERROR - Got an exception! Propagating...
Traceback (most recent call last):
  File "/home/airflow/.local/lib/python3.7/site-packages/sqlalchemy/engine/base.py", line 3141, in _wrap_pool_connect
    return fn()
  File "/home/airflow/.local/lib/python3.7/site-packages/sqlalchemy/pool/base.py", line 301, in connect
    return _ConnectionFairy._checkout(self)
  File "/home/airflow/.local/lib/python3.7/site-packages/sqlalchemy/pool/base.py", line 755, in _checkout
    fairy = _ConnectionRecord.checkout(pool)
  File "/home/airflow/.local/lib/python3.7/site-packages/sqlalchemy/pool/base.py", line 419, in checkout
    rec = pool._do_get()
  File "/home/airflow/.local/lib/python3.7/site-packages/sqlalchemy/pool/impl.py", line 145, in _do_get
    self._dec_overflow()
  File "/home/airflow/.local/lib/python3.7/site-packages/sqlalchemy/util/langhelpers.py", line 72, in __exit__
    with_traceback=exc_tb,
  File "/home/airflow/.local/lib/python3.7/site-packages/sqlalchemy/util/compat.py", line 211, in raise_
    raise exception
  File "/home/airflow/.local/lib/python3.7/site-packages/sqlalchemy/pool/impl.py", line 142, in _do_get
    return self._create_connection()
  File "/home/airflow/.local/lib/python3.7/site-packages/sqlalchemy/pool/base.py", line 247, in _create_connection
    return _ConnectionRecord(self)
  File "/home/airflow/.local/lib/python3.7/site-packages/sqlalchemy/pool/base.py", line 362, in __init__
    self.__connect(first_connect_check=True)
  File "/home/airflow/.local/lib/python3.7/site-packages/sqlalchemy/pool/base.py", line 605, in __connect
    pool.logger.debug("Error on connect(): %s", e)
  File "/home/airflow/.local/lib/python3.7/site-packages/sqlalchemy/util/langhelpers.py", line 72, in __exit__
    with_traceback=exc_tb,
  File "/home/airflow/.local/lib/python3.7/site-packages/sqlalchemy/util/compat.py", line 211, in raise_
    raise exception
  File "/home/airflow/.local/lib/python3.7/site-packages/sqlalchemy/pool/base.py", line 599, in __connect
    connection = pool._invoke_creator(self)
  File "/home/airflow/.local/lib/python3.7/site-packages/sqlalchemy/engine/create.py", line 578, in connect
    return dialect.connect(*cargs, **cparams)
  File "/home/airflow/.local/lib/python3.7/site-packages/sqlalchemy/engine/default.py", line 583, in connect
    return self.dbapi.connect(*cargs, **cparams)
  File "/home/airflow/.local/lib/python3.7/site-packages/psycopg2/__init__.py", line 122, in connect
    conn = _connect(dsn, connection_factory=connection_factory, **kwasync)
psycopg2.OperationalError: could not translate host name "postgres" to address: Temporary failure in name resolution


The above exception was the direct cause of the following exception:

Traceback (most recent call last):
  File "/home/airflow/.local/lib/python3.7/site-packages/airflow/dag_processing/processor.py", line 174, in _run_file_processor
    _handle_dag_file_processing()
  File "/home/airflow/.local/lib/python3.7/site-packages/airflow/dag_processing/processor.py", line 158, in _handle_dag_file_processing
    callback_requests=callback_requests,
  File "/home/airflow/.local/lib/python3.7/site-packages/airflow/utils/session.py", line 75, in wrapper
    return func(*args, session=session, **kwargs)
  File "/home/airflow/.local/lib/python3.7/site-packages/airflow/dag_processing/processor.py", line 756, in process_file
    self.update_import_errors(session, dagbag)
  File "/home/airflow/.local/lib/python3.7/site-packages/airflow/dag_processing/processor.py", line 544, in update_import_errors
    existing_import_error_files = [x.filename for x in session.query(errors.ImportError.filename).all()]
  File "/home/airflow/.local/lib/python3.7/site-packages/sqlalchemy/orm/query.py", line 2683, in all
    return self._iter().all()
  File "/home/airflow/.local/lib/python3.7/site-packages/sqlalchemy/orm/query.py", line 2821, in _iter
    execution_options={"_sa_orm_load_options": self.load_options},
  File "/home/airflow/.local/lib/python3.7/site-packages/sqlalchemy/orm/session.py", line 1669, in execute
    conn = self._connection_for_bind(bind, close_with_result=True)
  File "/home/airflow/.local/lib/python3.7/site-packages/sqlalchemy/orm/session.py", line 1520, in _connection_for_bind
    engine, execution_options
  File "/home/airflow/.local/lib/python3.7/site-packages/sqlalchemy/orm/session.py", line 747, in _connection_for_bind
    conn = bind.connect()
  File "/home/airflow/.local/lib/python3.7/site-packages/sqlalchemy/engine/base.py", line 3095, in connect
    return self._connection_cls(self, close_with_result=close_with_result)
  File "/home/airflow/.local/lib/python3.7/site-packages/sqlalchemy/engine/base.py", line 91, in __init__
    else engine.raw_connection()
  File "/home/airflow/.local/lib/python3.7/site-packages/sqlalchemy/engine/base.py", line 3174, in raw_connection
    return self._wrap_pool_connect(self.pool.connect, _connection)
  File "/home/airflow/.local/lib/python3.7/site-packages/sqlalchemy/engine/base.py", line 3145, in _wrap_pool_connect
    e, dialect, self
  File "/home/airflow/.local/lib/python3.7/site-packages/sqlalchemy/engine/base.py", line 2004, in _handle_dbapi_exception_noconnection
    sqlalchemy_exception, with_traceback=exc_info[2], from_=e
  File "/home/airflow/.local/lib/python3.7/site-packages/sqlalchemy/util/compat.py", line 211, in raise_
    raise exception
  File "/home/airflow/.local/lib/python3.7/site-packages/sqlalchemy/engine/base.py", line 3141, in _wrap_pool_connect
    return fn()
  File "/home/airflow/.local/lib/python3.7/site-packages/sqlalchemy/pool/base.py", line 301, in connect
    return _ConnectionFairy._checkout(self)
  File "/home/airflow/.local/lib/python3.7/site-packages/sqlalchemy/pool/base.py", line 755, in _checkout
    fairy = _ConnectionRecord.checkout(pool)
  File "/home/airflow/.local/lib/python3.7/site-packages/sqlalchemy/pool/base.py", line 419, in checkout
    rec = pool._do_get()
  File "/home/airflow/.local/lib/python3.7/site-packages/sqlalchemy/pool/impl.py", line 145, in _do_get
    self._dec_overflow()
  File "/home/airflow/.local/lib/python3.7/site-packages/sqlalchemy/util/langhelpers.py", line 72, in __exit__
    with_traceback=exc_tb,
  File "/home/airflow/.local/lib/python3.7/site-packages/sqlalchemy/util/compat.py", line 211, in raise_
    raise exception
  File "/home/airflow/.local/lib/python3.7/site-packages/sqlalchemy/pool/impl.py", line 142, in _do_get
    return self._create_connection()
  File "/home/airflow/.local/lib/python3.7/site-packages/sqlalchemy/pool/base.py", line 247, in _create_connection
    return _ConnectionRecord(self)
  File "/home/airflow/.local/lib/python3.7/site-packages/sqlalchemy/pool/base.py", line 362, in __init__
    self.__connect(first_connect_check=True)
  File "/home/airflow/.local/lib/python3.7/site-packages/sqlalchemy/pool/base.py", line 605, in __connect
    pool.logger.debug("Error on connect(): %s", e)
  File "/home/airflow/.local/lib/python3.7/site-packages/sqlalchemy/util/langhelpers.py", line 72, in __exit__
    with_traceback=exc_tb,
  File "/home/airflow/.local/lib/python3.7/site-packages/sqlalchemy/util/compat.py", line 211, in raise_
    raise exception
  File "/home/airflow/.local/lib/python3.7/site-packages/sqlalchemy/pool/base.py", line 599, in __connect
    connection = pool._invoke_creator(self)
  File "/home/airflow/.local/lib/python3.7/site-packages/sqlalchemy/engine/create.py", line 578, in connect
    return dialect.connect(*cargs, **cparams)
  File "/home/airflow/.local/lib/python3.7/site-packages/sqlalchemy/engine/default.py", line 583, in connect
    return self.dbapi.connect(*cargs, **cparams)
  File "/home/airflow/.local/lib/python3.7/site-packages/psycopg2/__init__.py", line 122, in connect
    conn = _connect(dsn, connection_factory=connection_factory, **kwasync)
sqlalchemy.exc.OperationalError: (psycopg2.OperationalError) could not translate host name "postgres" to address: Temporary failure in name resolution

(Background on this error at: http://sqlalche.me/e/14/e3q8)
[2023-04-26T23:09:32.681+0000] {processor.py:153} INFO - Started process (PID=196) to work on /opt/airflow/dags/noaa.py
[2023-04-26T23:09:35.161+0000] {processor.py:743} INFO - Processing file /opt/airflow/dags/noaa.py for tasks to queue
[2023-04-26T23:09:48.949+0000] {logging_mixin.py:137} INFO - [2023-04-26T23:09:38.066+0000] {dagbag.py:538} INFO - Filling up the DagBag from /opt/airflow/dags/noaa.py
[2023-04-26T23:09:58.446+0000] {logging_mixin.py:137} INFO - [2023-04-26T23:09:55.880+0000] {dagbag.py:343} ERROR - Failed to import: /opt/airflow/dags/noaa.py
Traceback (most recent call last):
  File "/home/airflow/.local/lib/python3.7/site-packages/airflow/models/dagbag.py", line 339, in parse
    loader.exec_module(new_module)
  File "<frozen importlib._bootstrap_external>", line 724, in exec_module
  File "<frozen importlib._bootstrap_external>", line 860, in get_code
  File "<frozen importlib._bootstrap_external>", line 791, in source_to_code
  File "<frozen importlib._bootstrap>", line 219, in _call_with_frames_removed
  File "/opt/airflow/dags/noaa.py", line 70
    ge_data_context_root_dir_with_checkpoint_name_pass = GreatExpectationsOperator(
    ^
IndentationError: unexpected indent
[2023-04-26T23:09:58.639+0000] {processor.py:755} WARNING - No viable dags retrieved from /opt/airflow/dags/noaa.py
[2023-04-26T23:11:18.184+0000] {processor.py:153} INFO - Started process (PID=199) to work on /opt/airflow/dags/noaa.py
[2023-04-26T23:11:18.632+0000] {processor.py:743} INFO - Processing file /opt/airflow/dags/noaa.py for tasks to queue
[2023-04-26T23:11:18.634+0000] {logging_mixin.py:137} INFO - [2023-04-26T23:11:18.634+0000] {dagbag.py:538} INFO - Filling up the DagBag from /opt/airflow/dags/noaa.py
[2023-04-26T23:11:18.915+0000] {logging_mixin.py:137} INFO - [2023-04-26T23:11:18.862+0000] {dagbag.py:343} ERROR - Failed to import: /opt/airflow/dags/noaa.py
Traceback (most recent call last):
  File "/home/airflow/.local/lib/python3.7/site-packages/airflow/models/dagbag.py", line 339, in parse
    loader.exec_module(new_module)
  File "<frozen importlib._bootstrap_external>", line 724, in exec_module
  File "<frozen importlib._bootstrap_external>", line 860, in get_code
  File "<frozen importlib._bootstrap_external>", line 791, in source_to_code
  File "<frozen importlib._bootstrap>", line 219, in _call_with_frames_removed
  File "/opt/airflow/dags/noaa.py", line 70
    ge_data_context_root_dir_with_checkpoint_name_pass = GreatExpectationsOperator(
    ^
IndentationError: unexpected indent
[2023-04-26T23:11:19.076+0000] {processor.py:755} WARNING - No viable dags retrieved from /opt/airflow/dags/noaa.py
[2023-04-26T23:11:20.735+0000] {processor.py:175} INFO - Processing /opt/airflow/dags/noaa.py took 7.703 seconds
[2023-04-26T23:11:54.007+0000] {processor.py:153} INFO - Started process (PID=213) to work on /opt/airflow/dags/noaa.py
[2023-04-26T23:11:54.758+0000] {processor.py:743} INFO - Processing file /opt/airflow/dags/noaa.py for tasks to queue
[2023-04-26T23:11:55.139+0000] {logging_mixin.py:137} INFO - [2023-04-26T23:11:54.975+0000] {dagbag.py:538} INFO - Filling up the DagBag from /opt/airflow/dags/noaa.py
[2023-04-26T23:11:56.267+0000] {logging_mixin.py:137} INFO - [2023-04-26T23:11:55.831+0000] {dagbag.py:343} ERROR - Failed to import: /opt/airflow/dags/noaa.py
Traceback (most recent call last):
  File "/home/airflow/.local/lib/python3.7/site-packages/airflow/models/dagbag.py", line 339, in parse
    loader.exec_module(new_module)
  File "<frozen importlib._bootstrap_external>", line 724, in exec_module
  File "<frozen importlib._bootstrap_external>", line 860, in get_code
  File "<frozen importlib._bootstrap_external>", line 791, in source_to_code
  File "<frozen importlib._bootstrap>", line 219, in _call_with_frames_removed
  File "/opt/airflow/dags/noaa.py", line 70
    ge_data_context_root_dir_with_checkpoint_name_pass = GreatExpectationsOperator(
    ^
IndentationError: unexpected indent
[2023-04-26T23:11:56.623+0000] {processor.py:755} WARNING - No viable dags retrieved from /opt/airflow/dags/noaa.py
[2023-04-26T23:12:04.001+0000] {processor.py:175} INFO - Processing /opt/airflow/dags/noaa.py took 10.275 seconds
[2023-04-26T23:12:54.288+0000] {processor.py:153} INFO - Started process (PID=222) to work on /opt/airflow/dags/noaa.py
[2023-04-26T23:12:54.468+0000] {processor.py:743} INFO - Processing file /opt/airflow/dags/noaa.py for tasks to queue
[2023-04-26T23:12:54.470+0000] {logging_mixin.py:137} INFO - [2023-04-26T23:12:54.470+0000] {dagbag.py:538} INFO - Filling up the DagBag from /opt/airflow/dags/noaa.py
[2023-04-26T23:12:56.345+0000] {logging_mixin.py:137} INFO - [2023-04-26T23:12:55.600+0000] {dagbag.py:343} ERROR - Failed to import: /opt/airflow/dags/noaa.py
Traceback (most recent call last):
  File "/home/airflow/.local/lib/python3.7/site-packages/airflow/models/dagbag.py", line 339, in parse
    loader.exec_module(new_module)
  File "<frozen importlib._bootstrap_external>", line 724, in exec_module
  File "<frozen importlib._bootstrap_external>", line 860, in get_code
  File "<frozen importlib._bootstrap_external>", line 791, in source_to_code
  File "<frozen importlib._bootstrap>", line 219, in _call_with_frames_removed
  File "/opt/airflow/dags/noaa.py", line 70
    ge_data_context_root_dir_with_checkpoint_name_pass = GreatExpectationsOperator(
    ^
IndentationError: unexpected indent
[2023-04-26T23:12:56.532+0000] {processor.py:755} WARNING - No viable dags retrieved from /opt/airflow/dags/noaa.py
[2023-04-26T23:13:01.417+0000] {processor.py:175} INFO - Processing /opt/airflow/dags/noaa.py took 7.562 seconds
[2023-04-26T23:14:22.983+0000] {processor.py:153} INFO - Started process (PID=226) to work on /opt/airflow/dags/noaa.py
[2023-04-26T23:14:24.050+0000] {processor.py:743} INFO - Processing file /opt/airflow/dags/noaa.py for tasks to queue
[2023-04-26T23:14:25.540+0000] {logging_mixin.py:137} INFO - [2023-04-26T23:14:24.816+0000] {dagbag.py:538} INFO - Filling up the DagBag from /opt/airflow/dags/noaa.py
[2023-04-26T23:14:39.545+0000] {logging_mixin.py:137} INFO - [2023-04-26T23:14:36.430+0000] {dagbag.py:343} ERROR - Failed to import: /opt/airflow/dags/noaa.py
Traceback (most recent call last):
  File "/home/airflow/.local/lib/python3.7/site-packages/airflow/models/dagbag.py", line 339, in parse
    loader.exec_module(new_module)
  File "<frozen importlib._bootstrap_external>", line 724, in exec_module
  File "<frozen importlib._bootstrap_external>", line 860, in get_code
  File "<frozen importlib._bootstrap_external>", line 791, in source_to_code
  File "<frozen importlib._bootstrap>", line 219, in _call_with_frames_removed
  File "/opt/airflow/dags/noaa.py", line 70
    ge_data_context_root_dir_with_checkpoint_name_pass = GreatExpectationsOperator(
    ^
IndentationError: unexpected indent
[2023-04-26T23:14:40.626+0000] {processor.py:755} WARNING - No viable dags retrieved from /opt/airflow/dags/noaa.py
[2023-04-26T23:15:03.732+0000] {processor.py:178} ERROR - Got an exception! Propagating...
Traceback (most recent call last):
  File "/home/airflow/.local/lib/python3.7/site-packages/sqlalchemy/engine/base.py", line 3141, in _wrap_pool_connect
    return fn()
  File "/home/airflow/.local/lib/python3.7/site-packages/sqlalchemy/pool/base.py", line 301, in connect
    return _ConnectionFairy._checkout(self)
  File "/home/airflow/.local/lib/python3.7/site-packages/sqlalchemy/pool/base.py", line 755, in _checkout
    fairy = _ConnectionRecord.checkout(pool)
  File "/home/airflow/.local/lib/python3.7/site-packages/sqlalchemy/pool/base.py", line 419, in checkout
    rec = pool._do_get()
  File "/home/airflow/.local/lib/python3.7/site-packages/sqlalchemy/pool/impl.py", line 145, in _do_get
    self._dec_overflow()
  File "/home/airflow/.local/lib/python3.7/site-packages/sqlalchemy/util/langhelpers.py", line 72, in __exit__
    with_traceback=exc_tb,
  File "/home/airflow/.local/lib/python3.7/site-packages/sqlalchemy/util/compat.py", line 211, in raise_
    raise exception
  File "/home/airflow/.local/lib/python3.7/site-packages/sqlalchemy/pool/impl.py", line 142, in _do_get
    return self._create_connection()
  File "/home/airflow/.local/lib/python3.7/site-packages/sqlalchemy/pool/base.py", line 247, in _create_connection
    return _ConnectionRecord(self)
  File "/home/airflow/.local/lib/python3.7/site-packages/sqlalchemy/pool/base.py", line 362, in __init__
    self.__connect(first_connect_check=True)
  File "/home/airflow/.local/lib/python3.7/site-packages/sqlalchemy/pool/base.py", line 605, in __connect
    pool.logger.debug("Error on connect(): %s", e)
  File "/home/airflow/.local/lib/python3.7/site-packages/sqlalchemy/util/langhelpers.py", line 72, in __exit__
    with_traceback=exc_tb,
  File "/home/airflow/.local/lib/python3.7/site-packages/sqlalchemy/util/compat.py", line 211, in raise_
    raise exception
  File "/home/airflow/.local/lib/python3.7/site-packages/sqlalchemy/pool/base.py", line 599, in __connect
    connection = pool._invoke_creator(self)
  File "/home/airflow/.local/lib/python3.7/site-packages/sqlalchemy/engine/create.py", line 578, in connect
    return dialect.connect(*cargs, **cparams)
  File "/home/airflow/.local/lib/python3.7/site-packages/sqlalchemy/engine/default.py", line 583, in connect
    return self.dbapi.connect(*cargs, **cparams)
  File "/home/airflow/.local/lib/python3.7/site-packages/psycopg2/__init__.py", line 122, in connect
    conn = _connect(dsn, connection_factory=connection_factory, **kwasync)
psycopg2.OperationalError: could not translate host name "postgres" to address: Temporary failure in name resolution


The above exception was the direct cause of the following exception:

Traceback (most recent call last):
  File "/home/airflow/.local/lib/python3.7/site-packages/airflow/dag_processing/processor.py", line 174, in _run_file_processor
    _handle_dag_file_processing()
  File "/home/airflow/.local/lib/python3.7/site-packages/airflow/dag_processing/processor.py", line 158, in _handle_dag_file_processing
    callback_requests=callback_requests,
  File "/home/airflow/.local/lib/python3.7/site-packages/airflow/utils/session.py", line 75, in wrapper
    return func(*args, session=session, **kwargs)
  File "/home/airflow/.local/lib/python3.7/site-packages/airflow/dag_processing/processor.py", line 756, in process_file
    self.update_import_errors(session, dagbag)
  File "/home/airflow/.local/lib/python3.7/site-packages/airflow/dag_processing/processor.py", line 544, in update_import_errors
    existing_import_error_files = [x.filename for x in session.query(errors.ImportError.filename).all()]
  File "/home/airflow/.local/lib/python3.7/site-packages/sqlalchemy/orm/query.py", line 2683, in all
    return self._iter().all()
  File "/home/airflow/.local/lib/python3.7/site-packages/sqlalchemy/orm/query.py", line 2821, in _iter
    execution_options={"_sa_orm_load_options": self.load_options},
  File "/home/airflow/.local/lib/python3.7/site-packages/sqlalchemy/orm/session.py", line 1669, in execute
    conn = self._connection_for_bind(bind, close_with_result=True)
  File "/home/airflow/.local/lib/python3.7/site-packages/sqlalchemy/orm/session.py", line 1520, in _connection_for_bind
    engine, execution_options
  File "/home/airflow/.local/lib/python3.7/site-packages/sqlalchemy/orm/session.py", line 747, in _connection_for_bind
    conn = bind.connect()
  File "/home/airflow/.local/lib/python3.7/site-packages/sqlalchemy/engine/base.py", line 3095, in connect
    return self._connection_cls(self, close_with_result=close_with_result)
  File "/home/airflow/.local/lib/python3.7/site-packages/sqlalchemy/engine/base.py", line 91, in __init__
    else engine.raw_connection()
  File "/home/airflow/.local/lib/python3.7/site-packages/sqlalchemy/engine/base.py", line 3174, in raw_connection
    return self._wrap_pool_connect(self.pool.connect, _connection)
  File "/home/airflow/.local/lib/python3.7/site-packages/sqlalchemy/engine/base.py", line 3145, in _wrap_pool_connect
    e, dialect, self
  File "/home/airflow/.local/lib/python3.7/site-packages/sqlalchemy/engine/base.py", line 2004, in _handle_dbapi_exception_noconnection
    sqlalchemy_exception, with_traceback=exc_info[2], from_=e
  File "/home/airflow/.local/lib/python3.7/site-packages/sqlalchemy/util/compat.py", line 211, in raise_
    raise exception
  File "/home/airflow/.local/lib/python3.7/site-packages/sqlalchemy/engine/base.py", line 3141, in _wrap_pool_connect
    return fn()
  File "/home/airflow/.local/lib/python3.7/site-packages/sqlalchemy/pool/base.py", line 301, in connect
    return _ConnectionFairy._checkout(self)
  File "/home/airflow/.local/lib/python3.7/site-packages/sqlalchemy/pool/base.py", line 755, in _checkout
    fairy = _ConnectionRecord.checkout(pool)
  File "/home/airflow/.local/lib/python3.7/site-packages/sqlalchemy/pool/base.py", line 419, in checkout
    rec = pool._do_get()
  File "/home/airflow/.local/lib/python3.7/site-packages/sqlalchemy/pool/impl.py", line 145, in _do_get
    self._dec_overflow()
  File "/home/airflow/.local/lib/python3.7/site-packages/sqlalchemy/util/langhelpers.py", line 72, in __exit__
    with_traceback=exc_tb,
  File "/home/airflow/.local/lib/python3.7/site-packages/sqlalchemy/util/compat.py", line 211, in raise_
    raise exception
  File "/home/airflow/.local/lib/python3.7/site-packages/sqlalchemy/pool/impl.py", line 142, in _do_get
    return self._create_connection()
  File "/home/airflow/.local/lib/python3.7/site-packages/sqlalchemy/pool/base.py", line 247, in _create_connection
    return _ConnectionRecord(self)
  File "/home/airflow/.local/lib/python3.7/site-packages/sqlalchemy/pool/base.py", line 362, in __init__
    self.__connect(first_connect_check=True)
  File "/home/airflow/.local/lib/python3.7/site-packages/sqlalchemy/pool/base.py", line 605, in __connect
    pool.logger.debug("Error on connect(): %s", e)
  File "/home/airflow/.local/lib/python3.7/site-packages/sqlalchemy/util/langhelpers.py", line 72, in __exit__
    with_traceback=exc_tb,
  File "/home/airflow/.local/lib/python3.7/site-packages/sqlalchemy/util/compat.py", line 211, in raise_
    raise exception
  File "/home/airflow/.local/lib/python3.7/site-packages/sqlalchemy/pool/base.py", line 599, in __connect
    connection = pool._invoke_creator(self)
  File "/home/airflow/.local/lib/python3.7/site-packages/sqlalchemy/engine/create.py", line 578, in connect
    return dialect.connect(*cargs, **cparams)
  File "/home/airflow/.local/lib/python3.7/site-packages/sqlalchemy/engine/default.py", line 583, in connect
    return self.dbapi.connect(*cargs, **cparams)
  File "/home/airflow/.local/lib/python3.7/site-packages/psycopg2/__init__.py", line 122, in connect
    conn = _connect(dsn, connection_factory=connection_factory, **kwasync)
sqlalchemy.exc.OperationalError: (psycopg2.OperationalError) could not translate host name "postgres" to address: Temporary failure in name resolution

(Background on this error at: http://sqlalche.me/e/14/e3q8)
[2023-04-26T23:17:46.638+0000] {processor.py:153} INFO - Started process (PID=227) to work on /opt/airflow/dags/noaa.py
[2023-04-26T23:17:46.978+0000] {processor.py:743} INFO - Processing file /opt/airflow/dags/noaa.py for tasks to queue
[2023-04-26T23:17:47.205+0000] {logging_mixin.py:137} INFO - [2023-04-26T23:17:47.152+0000] {dagbag.py:538} INFO - Filling up the DagBag from /opt/airflow/dags/noaa.py
[2023-04-26T23:17:48.254+0000] {logging_mixin.py:137} INFO - [2023-04-26T23:17:47.899+0000] {dagbag.py:343} ERROR - Failed to import: /opt/airflow/dags/noaa.py
Traceback (most recent call last):
  File "/home/airflow/.local/lib/python3.7/site-packages/airflow/models/dagbag.py", line 339, in parse
    loader.exec_module(new_module)
  File "<frozen importlib._bootstrap_external>", line 724, in exec_module
  File "<frozen importlib._bootstrap_external>", line 860, in get_code
  File "<frozen importlib._bootstrap_external>", line 791, in source_to_code
  File "<frozen importlib._bootstrap>", line 219, in _call_with_frames_removed
  File "/opt/airflow/dags/noaa.py", line 70
    ge_data_context_root_dir_with_checkpoint_name_pass = GreatExpectationsOperator(
    ^
IndentationError: unexpected indent
[2023-04-26T23:17:48.472+0000] {processor.py:755} WARNING - No viable dags retrieved from /opt/airflow/dags/noaa.py
[2023-04-26T23:17:55.854+0000] {processor.py:175} INFO - Processing /opt/airflow/dags/noaa.py took 11.066 seconds
[2023-04-26T23:18:41.113+0000] {processor.py:153} INFO - Started process (PID=248) to work on /opt/airflow/dags/noaa.py
[2023-04-26T23:18:41.663+0000] {processor.py:743} INFO - Processing file /opt/airflow/dags/noaa.py for tasks to queue
[2023-04-26T23:18:42.264+0000] {logging_mixin.py:137} INFO - [2023-04-26T23:18:42.183+0000] {dagbag.py:538} INFO - Filling up the DagBag from /opt/airflow/dags/noaa.py
[2023-04-26T23:18:53.334+0000] {logging_mixin.py:137} INFO - [2023-04-26T23:18:49.010+0000] {dagbag.py:343} ERROR - Failed to import: /opt/airflow/dags/noaa.py
Traceback (most recent call last):
  File "/home/airflow/.local/lib/python3.7/site-packages/airflow/models/dagbag.py", line 339, in parse
    loader.exec_module(new_module)
  File "<frozen importlib._bootstrap_external>", line 724, in exec_module
  File "<frozen importlib._bootstrap_external>", line 860, in get_code
  File "<frozen importlib._bootstrap_external>", line 791, in source_to_code
  File "<frozen importlib._bootstrap>", line 219, in _call_with_frames_removed
  File "/opt/airflow/dags/noaa.py", line 70
    ge_data_context_root_dir_with_checkpoint_name_pass = GreatExpectationsOperator(
    ^
IndentationError: unexpected indent
[2023-04-26T23:18:53.865+0000] {processor.py:755} WARNING - No viable dags retrieved from /opt/airflow/dags/noaa.py
[2023-04-26T23:21:02.740+0000] {processor.py:153} INFO - Started process (PID=259) to work on /opt/airflow/dags/noaa.py
[2023-04-26T23:21:03.457+0000] {processor.py:743} INFO - Processing file /opt/airflow/dags/noaa.py for tasks to queue
[2023-04-26T23:21:05.071+0000] {logging_mixin.py:137} INFO - [2023-04-26T23:21:04.831+0000] {dagbag.py:538} INFO - Filling up the DagBag from /opt/airflow/dags/noaa.py
[2023-04-26T23:21:08.828+0000] {logging_mixin.py:137} INFO - [2023-04-26T23:21:07.971+0000] {dagbag.py:343} ERROR - Failed to import: /opt/airflow/dags/noaa.py
Traceback (most recent call last):
  File "/home/airflow/.local/lib/python3.7/site-packages/airflow/models/dagbag.py", line 339, in parse
    loader.exec_module(new_module)
  File "<frozen importlib._bootstrap_external>", line 724, in exec_module
  File "<frozen importlib._bootstrap_external>", line 860, in get_code
  File "<frozen importlib._bootstrap_external>", line 791, in source_to_code
  File "<frozen importlib._bootstrap>", line 219, in _call_with_frames_removed
  File "/opt/airflow/dags/noaa.py", line 70
    ge_data_context_root_dir_with_checkpoint_name_pass = GreatExpectationsOperator(
    ^
IndentationError: unexpected indent
[2023-04-26T23:21:09.226+0000] {processor.py:755} WARNING - No viable dags retrieved from /opt/airflow/dags/noaa.py
[2023-04-26T23:22:49.176+0000] {processor.py:153} INFO - Started process (PID=269) to work on /opt/airflow/dags/noaa.py
[2023-04-26T23:22:53.245+0000] {processor.py:743} INFO - Processing file /opt/airflow/dags/noaa.py for tasks to queue
[2023-04-26T23:22:53.575+0000] {logging_mixin.py:137} INFO - [2023-04-26T23:22:53.398+0000] {dagbag.py:538} INFO - Filling up the DagBag from /opt/airflow/dags/noaa.py
[2023-04-26T23:23:00.519+0000] {logging_mixin.py:137} INFO - [2023-04-26T23:22:56.926+0000] {dagbag.py:343} ERROR - Failed to import: /opt/airflow/dags/noaa.py
Traceback (most recent call last):
  File "/home/airflow/.local/lib/python3.7/site-packages/airflow/models/dagbag.py", line 339, in parse
    loader.exec_module(new_module)
  File "<frozen importlib._bootstrap_external>", line 724, in exec_module
  File "<frozen importlib._bootstrap_external>", line 860, in get_code
  File "<frozen importlib._bootstrap_external>", line 791, in source_to_code
  File "<frozen importlib._bootstrap>", line 219, in _call_with_frames_removed
  File "/opt/airflow/dags/noaa.py", line 70
    ge_data_context_root_dir_with_checkpoint_name_pass = GreatExpectationsOperator(
    ^
IndentationError: unexpected indent
[2023-04-26T23:23:02.603+0000] {processor.py:755} WARNING - No viable dags retrieved from /opt/airflow/dags/noaa.py
[2023-04-26T23:24:25.064+0000] {processor.py:153} INFO - Started process (PID=278) to work on /opt/airflow/dags/noaa.py
[2023-04-26T23:24:27.541+0000] {processor.py:743} INFO - Processing file /opt/airflow/dags/noaa.py for tasks to queue
[2023-04-26T23:24:27.603+0000] {logging_mixin.py:137} INFO - [2023-04-26T23:24:27.587+0000] {dagbag.py:538} INFO - Filling up the DagBag from /opt/airflow/dags/noaa.py
[2023-04-26T23:24:29.909+0000] {logging_mixin.py:137} INFO - [2023-04-26T23:24:29.156+0000] {dagbag.py:343} ERROR - Failed to import: /opt/airflow/dags/noaa.py
Traceback (most recent call last):
  File "/home/airflow/.local/lib/python3.7/site-packages/airflow/models/dagbag.py", line 339, in parse
    loader.exec_module(new_module)
  File "<frozen importlib._bootstrap_external>", line 724, in exec_module
  File "<frozen importlib._bootstrap_external>", line 860, in get_code
  File "<frozen importlib._bootstrap_external>", line 791, in source_to_code
  File "<frozen importlib._bootstrap>", line 219, in _call_with_frames_removed
  File "/opt/airflow/dags/noaa.py", line 70
    ge_data_context_root_dir_with_checkpoint_name_pass = GreatExpectationsOperator(
    ^
IndentationError: unexpected indent
[2023-04-26T23:24:29.944+0000] {processor.py:755} WARNING - No viable dags retrieved from /opt/airflow/dags/noaa.py
[2023-04-26T23:24:46.721+0000] {processor.py:178} ERROR - Got an exception! Propagating...
Traceback (most recent call last):
  File "/home/airflow/.local/lib/python3.7/site-packages/sqlalchemy/engine/base.py", line 3141, in _wrap_pool_connect
    return fn()
  File "/home/airflow/.local/lib/python3.7/site-packages/sqlalchemy/pool/base.py", line 301, in connect
    return _ConnectionFairy._checkout(self)
  File "/home/airflow/.local/lib/python3.7/site-packages/sqlalchemy/pool/base.py", line 755, in _checkout
    fairy = _ConnectionRecord.checkout(pool)
  File "/home/airflow/.local/lib/python3.7/site-packages/sqlalchemy/pool/base.py", line 419, in checkout
    rec = pool._do_get()
  File "/home/airflow/.local/lib/python3.7/site-packages/sqlalchemy/pool/impl.py", line 145, in _do_get
    self._dec_overflow()
  File "/home/airflow/.local/lib/python3.7/site-packages/sqlalchemy/util/langhelpers.py", line 72, in __exit__
    with_traceback=exc_tb,
  File "/home/airflow/.local/lib/python3.7/site-packages/sqlalchemy/util/compat.py", line 211, in raise_
    raise exception
  File "/home/airflow/.local/lib/python3.7/site-packages/sqlalchemy/pool/impl.py", line 142, in _do_get
    return self._create_connection()
  File "/home/airflow/.local/lib/python3.7/site-packages/sqlalchemy/pool/base.py", line 247, in _create_connection
    return _ConnectionRecord(self)
  File "/home/airflow/.local/lib/python3.7/site-packages/sqlalchemy/pool/base.py", line 362, in __init__
    self.__connect(first_connect_check=True)
  File "/home/airflow/.local/lib/python3.7/site-packages/sqlalchemy/pool/base.py", line 605, in __connect
    pool.logger.debug("Error on connect(): %s", e)
  File "/home/airflow/.local/lib/python3.7/site-packages/sqlalchemy/util/langhelpers.py", line 72, in __exit__
    with_traceback=exc_tb,
  File "/home/airflow/.local/lib/python3.7/site-packages/sqlalchemy/util/compat.py", line 211, in raise_
    raise exception
  File "/home/airflow/.local/lib/python3.7/site-packages/sqlalchemy/pool/base.py", line 599, in __connect
    connection = pool._invoke_creator(self)
  File "/home/airflow/.local/lib/python3.7/site-packages/sqlalchemy/engine/create.py", line 578, in connect
    return dialect.connect(*cargs, **cparams)
  File "/home/airflow/.local/lib/python3.7/site-packages/sqlalchemy/engine/default.py", line 583, in connect
    return self.dbapi.connect(*cargs, **cparams)
  File "/home/airflow/.local/lib/python3.7/site-packages/psycopg2/__init__.py", line 122, in connect
    conn = _connect(dsn, connection_factory=connection_factory, **kwasync)
psycopg2.OperationalError: could not translate host name "postgres" to address: Temporary failure in name resolution


The above exception was the direct cause of the following exception:

Traceback (most recent call last):
  File "/home/airflow/.local/lib/python3.7/site-packages/airflow/dag_processing/processor.py", line 174, in _run_file_processor
    _handle_dag_file_processing()
  File "/home/airflow/.local/lib/python3.7/site-packages/airflow/dag_processing/processor.py", line 158, in _handle_dag_file_processing
    callback_requests=callback_requests,
  File "/home/airflow/.local/lib/python3.7/site-packages/airflow/utils/session.py", line 75, in wrapper
    return func(*args, session=session, **kwargs)
  File "/home/airflow/.local/lib/python3.7/site-packages/airflow/dag_processing/processor.py", line 756, in process_file
    self.update_import_errors(session, dagbag)
  File "/home/airflow/.local/lib/python3.7/site-packages/airflow/dag_processing/processor.py", line 544, in update_import_errors
    existing_import_error_files = [x.filename for x in session.query(errors.ImportError.filename).all()]
  File "/home/airflow/.local/lib/python3.7/site-packages/sqlalchemy/orm/query.py", line 2683, in all
    return self._iter().all()
  File "/home/airflow/.local/lib/python3.7/site-packages/sqlalchemy/orm/query.py", line 2821, in _iter
    execution_options={"_sa_orm_load_options": self.load_options},
  File "/home/airflow/.local/lib/python3.7/site-packages/sqlalchemy/orm/session.py", line 1669, in execute
    conn = self._connection_for_bind(bind, close_with_result=True)
  File "/home/airflow/.local/lib/python3.7/site-packages/sqlalchemy/orm/session.py", line 1520, in _connection_for_bind
    engine, execution_options
  File "/home/airflow/.local/lib/python3.7/site-packages/sqlalchemy/orm/session.py", line 747, in _connection_for_bind
    conn = bind.connect()
  File "/home/airflow/.local/lib/python3.7/site-packages/sqlalchemy/engine/base.py", line 3095, in connect
    return self._connection_cls(self, close_with_result=close_with_result)
  File "/home/airflow/.local/lib/python3.7/site-packages/sqlalchemy/engine/base.py", line 91, in __init__
    else engine.raw_connection()
  File "/home/airflow/.local/lib/python3.7/site-packages/sqlalchemy/engine/base.py", line 3174, in raw_connection
    return self._wrap_pool_connect(self.pool.connect, _connection)
  File "/home/airflow/.local/lib/python3.7/site-packages/sqlalchemy/engine/base.py", line 3145, in _wrap_pool_connect
    e, dialect, self
  File "/home/airflow/.local/lib/python3.7/site-packages/sqlalchemy/engine/base.py", line 2004, in _handle_dbapi_exception_noconnection
    sqlalchemy_exception, with_traceback=exc_info[2], from_=e
  File "/home/airflow/.local/lib/python3.7/site-packages/sqlalchemy/util/compat.py", line 211, in raise_
    raise exception
  File "/home/airflow/.local/lib/python3.7/site-packages/sqlalchemy/engine/base.py", line 3141, in _wrap_pool_connect
    return fn()
  File "/home/airflow/.local/lib/python3.7/site-packages/sqlalchemy/pool/base.py", line 301, in connect
    return _ConnectionFairy._checkout(self)
  File "/home/airflow/.local/lib/python3.7/site-packages/sqlalchemy/pool/base.py", line 755, in _checkout
    fairy = _ConnectionRecord.checkout(pool)
  File "/home/airflow/.local/lib/python3.7/site-packages/sqlalchemy/pool/base.py", line 419, in checkout
    rec = pool._do_get()
  File "/home/airflow/.local/lib/python3.7/site-packages/sqlalchemy/pool/impl.py", line 145, in _do_get
    self._dec_overflow()
  File "/home/airflow/.local/lib/python3.7/site-packages/sqlalchemy/util/langhelpers.py", line 72, in __exit__
    with_traceback=exc_tb,
  File "/home/airflow/.local/lib/python3.7/site-packages/sqlalchemy/util/compat.py", line 211, in raise_
    raise exception
  File "/home/airflow/.local/lib/python3.7/site-packages/sqlalchemy/pool/impl.py", line 142, in _do_get
    return self._create_connection()
  File "/home/airflow/.local/lib/python3.7/site-packages/sqlalchemy/pool/base.py", line 247, in _create_connection
    return _ConnectionRecord(self)
  File "/home/airflow/.local/lib/python3.7/site-packages/sqlalchemy/pool/base.py", line 362, in __init__
    self.__connect(first_connect_check=True)
  File "/home/airflow/.local/lib/python3.7/site-packages/sqlalchemy/pool/base.py", line 605, in __connect
    pool.logger.debug("Error on connect(): %s", e)
  File "/home/airflow/.local/lib/python3.7/site-packages/sqlalchemy/util/langhelpers.py", line 72, in __exit__
    with_traceback=exc_tb,
  File "/home/airflow/.local/lib/python3.7/site-packages/sqlalchemy/util/compat.py", line 211, in raise_
    raise exception
  File "/home/airflow/.local/lib/python3.7/site-packages/sqlalchemy/pool/base.py", line 599, in __connect
    connection = pool._invoke_creator(self)
  File "/home/airflow/.local/lib/python3.7/site-packages/sqlalchemy/engine/create.py", line 578, in connect
    return dialect.connect(*cargs, **cparams)
  File "/home/airflow/.local/lib/python3.7/site-packages/sqlalchemy/engine/default.py", line 583, in connect
    return self.dbapi.connect(*cargs, **cparams)
  File "/home/airflow/.local/lib/python3.7/site-packages/psycopg2/__init__.py", line 122, in connect
    conn = _connect(dsn, connection_factory=connection_factory, **kwasync)
sqlalchemy.exc.OperationalError: (psycopg2.OperationalError) could not translate host name "postgres" to address: Temporary failure in name resolution

(Background on this error at: http://sqlalche.me/e/14/e3q8)
[2023-04-26T23:26:08.781+0000] {processor.py:153} INFO - Started process (PID=282) to work on /opt/airflow/dags/noaa.py
[2023-04-26T23:26:08.908+0000] {processor.py:743} INFO - Processing file /opt/airflow/dags/noaa.py for tasks to queue
[2023-04-26T23:26:09.052+0000] {logging_mixin.py:137} INFO - [2023-04-26T23:26:09.052+0000] {dagbag.py:538} INFO - Filling up the DagBag from /opt/airflow/dags/noaa.py
[2023-04-26T23:26:09.770+0000] {logging_mixin.py:137} INFO - [2023-04-26T23:26:09.506+0000] {dagbag.py:343} ERROR - Failed to import: /opt/airflow/dags/noaa.py
Traceback (most recent call last):
  File "/home/airflow/.local/lib/python3.7/site-packages/airflow/models/dagbag.py", line 339, in parse
    loader.exec_module(new_module)
  File "<frozen importlib._bootstrap_external>", line 724, in exec_module
  File "<frozen importlib._bootstrap_external>", line 860, in get_code
  File "<frozen importlib._bootstrap_external>", line 791, in source_to_code
  File "<frozen importlib._bootstrap>", line 219, in _call_with_frames_removed
  File "/opt/airflow/dags/noaa.py", line 70
    ge_data_context_root_dir_with_checkpoint_name_pass = GreatExpectationsOperator(
    ^
IndentationError: unexpected indent
[2023-04-26T23:26:10.091+0000] {processor.py:755} WARNING - No viable dags retrieved from /opt/airflow/dags/noaa.py
[2023-04-26T23:44:29.586+0000] {processor.py:153} INFO - Started process (PID=354) to work on /opt/airflow/dags/noaa.py
[2023-04-26T23:44:29.619+0000] {processor.py:743} INFO - Processing file /opt/airflow/dags/noaa.py for tasks to queue
[2023-04-26T23:44:29.643+0000] {logging_mixin.py:137} INFO - [2023-04-26T23:44:29.643+0000] {dagbag.py:538} INFO - Filling up the DagBag from /opt/airflow/dags/noaa.py
[2023-04-26T23:44:29.698+0000] {logging_mixin.py:137} INFO - [2023-04-26T23:44:29.668+0000] {dagbag.py:343} ERROR - Failed to import: /opt/airflow/dags/noaa.py
Traceback (most recent call last):
  File "/home/airflow/.local/lib/python3.7/site-packages/airflow/models/dagbag.py", line 339, in parse
    loader.exec_module(new_module)
  File "<frozen importlib._bootstrap_external>", line 724, in exec_module
  File "<frozen importlib._bootstrap_external>", line 860, in get_code
  File "<frozen importlib._bootstrap_external>", line 791, in source_to_code
  File "<frozen importlib._bootstrap>", line 219, in _call_with_frames_removed
  File "/opt/airflow/dags/noaa.py", line 70
    ge_data_context_root_dir_with_checkpoint_name_pass = GreatExpectationsOperator(
    ^
IndentationError: unexpected indent
[2023-04-26T23:44:29.698+0000] {processor.py:755} WARNING - No viable dags retrieved from /opt/airflow/dags/noaa.py
[2023-04-26T23:44:30.073+0000] {processor.py:175} INFO - Processing /opt/airflow/dags/noaa.py took 0.497 seconds
[2023-04-26T23:45:04.054+0000] {processor.py:153} INFO - Started process (PID=368) to work on /opt/airflow/dags/noaa.py
[2023-04-26T23:45:04.112+0000] {processor.py:743} INFO - Processing file /opt/airflow/dags/noaa.py for tasks to queue
[2023-04-26T23:45:04.116+0000] {logging_mixin.py:137} INFO - [2023-04-26T23:45:04.115+0000] {dagbag.py:538} INFO - Filling up the DagBag from /opt/airflow/dags/noaa.py
[2023-04-26T23:45:06.210+0000] {logging_mixin.py:137} INFO - [2023-04-26T23:45:06.138+0000] {dagbag.py:343} ERROR - Failed to import: /opt/airflow/dags/noaa.py
Traceback (most recent call last):
  File "/home/airflow/.local/lib/python3.7/site-packages/airflow/models/dagbag.py", line 339, in parse
    loader.exec_module(new_module)
  File "<frozen importlib._bootstrap_external>", line 724, in exec_module
  File "<frozen importlib._bootstrap_external>", line 860, in get_code
  File "<frozen importlib._bootstrap_external>", line 791, in source_to_code
  File "<frozen importlib._bootstrap>", line 219, in _call_with_frames_removed
  File "/opt/airflow/dags/noaa.py", line 70
    ge_data_context_root_dir_with_checkpoint_name_pass = GreatExpectationsOperator(
    ^
IndentationError: unexpected indent
[2023-04-26T23:45:06.252+0000] {processor.py:755} WARNING - No viable dags retrieved from /opt/airflow/dags/noaa.py
[2023-04-26T23:45:07.168+0000] {processor.py:175} INFO - Processing /opt/airflow/dags/noaa.py took 4.135 seconds
[2023-04-26T23:45:37.455+0000] {processor.py:153} INFO - Started process (PID=389) to work on /opt/airflow/dags/noaa.py
[2023-04-26T23:45:37.461+0000] {processor.py:743} INFO - Processing file /opt/airflow/dags/noaa.py for tasks to queue
[2023-04-26T23:45:37.465+0000] {logging_mixin.py:137} INFO - [2023-04-26T23:45:37.465+0000] {dagbag.py:538} INFO - Filling up the DagBag from /opt/airflow/dags/noaa.py
[2023-04-26T23:45:37.471+0000] {logging_mixin.py:137} INFO - [2023-04-26T23:45:37.470+0000] {dagbag.py:343} ERROR - Failed to import: /opt/airflow/dags/noaa.py
Traceback (most recent call last):
  File "/home/airflow/.local/lib/python3.7/site-packages/airflow/models/dagbag.py", line 339, in parse
    loader.exec_module(new_module)
  File "<frozen importlib._bootstrap_external>", line 724, in exec_module
  File "<frozen importlib._bootstrap_external>", line 860, in get_code
  File "<frozen importlib._bootstrap_external>", line 791, in source_to_code
  File "<frozen importlib._bootstrap>", line 219, in _call_with_frames_removed
  File "/opt/airflow/dags/noaa.py", line 70
    ge_data_context_root_dir_with_checkpoint_name_pass = GreatExpectationsOperator(
    ^
IndentationError: unexpected indent
[2023-04-26T23:45:37.472+0000] {processor.py:755} WARNING - No viable dags retrieved from /opt/airflow/dags/noaa.py
[2023-04-26T23:45:37.520+0000] {processor.py:175} INFO - Processing /opt/airflow/dags/noaa.py took 0.072 seconds
[2023-04-26T23:46:07.577+0000] {processor.py:153} INFO - Started process (PID=409) to work on /opt/airflow/dags/noaa.py
[2023-04-26T23:46:07.579+0000] {processor.py:743} INFO - Processing file /opt/airflow/dags/noaa.py for tasks to queue
[2023-04-26T23:46:07.580+0000] {logging_mixin.py:137} INFO - [2023-04-26T23:46:07.580+0000] {dagbag.py:538} INFO - Filling up the DagBag from /opt/airflow/dags/noaa.py
[2023-04-26T23:46:07.588+0000] {logging_mixin.py:137} INFO - [2023-04-26T23:46:07.584+0000] {dagbag.py:343} ERROR - Failed to import: /opt/airflow/dags/noaa.py
Traceback (most recent call last):
  File "/home/airflow/.local/lib/python3.7/site-packages/airflow/models/dagbag.py", line 339, in parse
    loader.exec_module(new_module)
  File "<frozen importlib._bootstrap_external>", line 724, in exec_module
  File "<frozen importlib._bootstrap_external>", line 860, in get_code
  File "<frozen importlib._bootstrap_external>", line 791, in source_to_code
  File "<frozen importlib._bootstrap>", line 219, in _call_with_frames_removed
  File "/opt/airflow/dags/noaa.py", line 70
    ge_data_context_root_dir_with_checkpoint_name_pass = GreatExpectationsOperator(
    ^
IndentationError: unexpected indent
[2023-04-26T23:46:07.589+0000] {processor.py:755} WARNING - No viable dags retrieved from /opt/airflow/dags/noaa.py
[2023-04-26T23:46:07.618+0000] {processor.py:175} INFO - Processing /opt/airflow/dags/noaa.py took 0.045 seconds
[2023-04-26T23:46:38.625+0000] {processor.py:153} INFO - Started process (PID=430) to work on /opt/airflow/dags/noaa.py
[2023-04-26T23:46:38.626+0000] {processor.py:743} INFO - Processing file /opt/airflow/dags/noaa.py for tasks to queue
[2023-04-26T23:46:38.627+0000] {logging_mixin.py:137} INFO - [2023-04-26T23:46:38.627+0000] {dagbag.py:538} INFO - Filling up the DagBag from /opt/airflow/dags/noaa.py
[2023-04-26T23:46:38.631+0000] {logging_mixin.py:137} INFO - [2023-04-26T23:46:38.628+0000] {dagbag.py:343} ERROR - Failed to import: /opt/airflow/dags/noaa.py
Traceback (most recent call last):
  File "/home/airflow/.local/lib/python3.7/site-packages/airflow/models/dagbag.py", line 339, in parse
    loader.exec_module(new_module)
  File "<frozen importlib._bootstrap_external>", line 724, in exec_module
  File "<frozen importlib._bootstrap_external>", line 860, in get_code
  File "<frozen importlib._bootstrap_external>", line 791, in source_to_code
  File "<frozen importlib._bootstrap>", line 219, in _call_with_frames_removed
  File "/opt/airflow/dags/noaa.py", line 70
    ge_data_context_root_dir_with_checkpoint_name_pass = GreatExpectationsOperator(
    ^
IndentationError: unexpected indent
[2023-04-26T23:46:38.631+0000] {processor.py:755} WARNING - No viable dags retrieved from /opt/airflow/dags/noaa.py
[2023-04-26T23:46:38.656+0000] {processor.py:175} INFO - Processing /opt/airflow/dags/noaa.py took 0.034 seconds
[2023-04-26T23:46:50.707+0000] {processor.py:153} INFO - Started process (PID=441) to work on /opt/airflow/dags/noaa.py
[2023-04-26T23:46:50.708+0000] {processor.py:743} INFO - Processing file /opt/airflow/dags/noaa.py for tasks to queue
[2023-04-26T23:46:50.709+0000] {logging_mixin.py:137} INFO - [2023-04-26T23:46:50.708+0000] {dagbag.py:538} INFO - Filling up the DagBag from /opt/airflow/dags/noaa.py
[2023-04-26T23:46:50.712+0000] {logging_mixin.py:137} INFO - [2023-04-26T23:46:50.710+0000] {dagbag.py:343} ERROR - Failed to import: /opt/airflow/dags/noaa.py
Traceback (most recent call last):
  File "/home/airflow/.local/lib/python3.7/site-packages/airflow/models/dagbag.py", line 339, in parse
    loader.exec_module(new_module)
  File "<frozen importlib._bootstrap_external>", line 724, in exec_module
  File "<frozen importlib._bootstrap_external>", line 860, in get_code
  File "<frozen importlib._bootstrap_external>", line 791, in source_to_code
  File "<frozen importlib._bootstrap>", line 219, in _call_with_frames_removed
  File "/opt/airflow/dags/noaa.py", line 70
    ge_data_context_root_dir_with_checkpoint_name_pass = GreatExpectationsOperator(
    ^
IndentationError: unexpected indent
[2023-04-26T23:46:50.713+0000] {processor.py:755} WARNING - No viable dags retrieved from /opt/airflow/dags/noaa.py
[2023-04-26T23:46:50.738+0000] {processor.py:175} INFO - Processing /opt/airflow/dags/noaa.py took 0.034 seconds
[2023-04-26T23:47:20.877+0000] {processor.py:153} INFO - Started process (PID=461) to work on /opt/airflow/dags/noaa.py
[2023-04-26T23:47:20.879+0000] {processor.py:743} INFO - Processing file /opt/airflow/dags/noaa.py for tasks to queue
[2023-04-26T23:47:20.880+0000] {logging_mixin.py:137} INFO - [2023-04-26T23:47:20.879+0000] {dagbag.py:538} INFO - Filling up the DagBag from /opt/airflow/dags/noaa.py
[2023-04-26T23:47:20.882+0000] {logging_mixin.py:137} INFO - [2023-04-26T23:47:20.881+0000] {dagbag.py:343} ERROR - Failed to import: /opt/airflow/dags/noaa.py
Traceback (most recent call last):
  File "/home/airflow/.local/lib/python3.7/site-packages/airflow/models/dagbag.py", line 339, in parse
    loader.exec_module(new_module)
  File "<frozen importlib._bootstrap_external>", line 724, in exec_module
  File "<frozen importlib._bootstrap_external>", line 860, in get_code
  File "<frozen importlib._bootstrap_external>", line 791, in source_to_code
  File "<frozen importlib._bootstrap>", line 219, in _call_with_frames_removed
  File "/opt/airflow/dags/noaa.py", line 70
    ge_data_context_root_dir_with_checkpoint_name_pass = GreatExpectationsOperator(
    ^
IndentationError: unexpected indent
[2023-04-26T23:47:20.882+0000] {processor.py:755} WARNING - No viable dags retrieved from /opt/airflow/dags/noaa.py
[2023-04-26T23:47:20.905+0000] {processor.py:175} INFO - Processing /opt/airflow/dags/noaa.py took 0.039 seconds
[2023-04-26T23:47:51.031+0000] {processor.py:153} INFO - Started process (PID=492) to work on /opt/airflow/dags/noaa.py
[2023-04-26T23:47:51.033+0000] {processor.py:743} INFO - Processing file /opt/airflow/dags/noaa.py for tasks to queue
[2023-04-26T23:47:51.033+0000] {logging_mixin.py:137} INFO - [2023-04-26T23:47:51.033+0000] {dagbag.py:538} INFO - Filling up the DagBag from /opt/airflow/dags/noaa.py
[2023-04-26T23:47:51.037+0000] {logging_mixin.py:137} INFO - [2023-04-26T23:47:51.035+0000] {dagbag.py:343} ERROR - Failed to import: /opt/airflow/dags/noaa.py
Traceback (most recent call last):
  File "/home/airflow/.local/lib/python3.7/site-packages/airflow/models/dagbag.py", line 339, in parse
    loader.exec_module(new_module)
  File "<frozen importlib._bootstrap_external>", line 724, in exec_module
  File "<frozen importlib._bootstrap_external>", line 860, in get_code
  File "<frozen importlib._bootstrap_external>", line 791, in source_to_code
  File "<frozen importlib._bootstrap>", line 219, in _call_with_frames_removed
  File "/opt/airflow/dags/noaa.py", line 70
    ge_data_context_root_dir_with_checkpoint_name_pass = GreatExpectationsOperator(
    ^
IndentationError: unexpected indent
[2023-04-26T23:47:51.038+0000] {processor.py:755} WARNING - No viable dags retrieved from /opt/airflow/dags/noaa.py
[2023-04-26T23:47:51.062+0000] {processor.py:175} INFO - Processing /opt/airflow/dags/noaa.py took 0.034 seconds
[2023-04-26T23:48:21.235+0000] {processor.py:153} INFO - Started process (PID=513) to work on /opt/airflow/dags/noaa.py
[2023-04-26T23:48:21.237+0000] {processor.py:743} INFO - Processing file /opt/airflow/dags/noaa.py for tasks to queue
[2023-04-26T23:48:21.238+0000] {logging_mixin.py:137} INFO - [2023-04-26T23:48:21.238+0000] {dagbag.py:538} INFO - Filling up the DagBag from /opt/airflow/dags/noaa.py
[2023-04-26T23:48:21.241+0000] {logging_mixin.py:137} INFO - [2023-04-26T23:48:21.239+0000] {dagbag.py:343} ERROR - Failed to import: /opt/airflow/dags/noaa.py
Traceback (most recent call last):
  File "/home/airflow/.local/lib/python3.7/site-packages/airflow/models/dagbag.py", line 339, in parse
    loader.exec_module(new_module)
  File "<frozen importlib._bootstrap_external>", line 724, in exec_module
  File "<frozen importlib._bootstrap_external>", line 860, in get_code
  File "<frozen importlib._bootstrap_external>", line 791, in source_to_code
  File "<frozen importlib._bootstrap>", line 219, in _call_with_frames_removed
  File "/opt/airflow/dags/noaa.py", line 70
    ge_data_context_root_dir_with_checkpoint_name_pass = GreatExpectationsOperator(
    ^
IndentationError: unexpected indent
[2023-04-26T23:48:21.241+0000] {processor.py:755} WARNING - No viable dags retrieved from /opt/airflow/dags/noaa.py
[2023-04-26T23:48:21.301+0000] {processor.py:175} INFO - Processing /opt/airflow/dags/noaa.py took 0.077 seconds
[2023-04-26T23:48:51.430+0000] {processor.py:153} INFO - Started process (PID=544) to work on /opt/airflow/dags/noaa.py
[2023-04-26T23:48:51.436+0000] {processor.py:743} INFO - Processing file /opt/airflow/dags/noaa.py for tasks to queue
[2023-04-26T23:48:51.437+0000] {logging_mixin.py:137} INFO - [2023-04-26T23:48:51.437+0000] {dagbag.py:538} INFO - Filling up the DagBag from /opt/airflow/dags/noaa.py
[2023-04-26T23:48:51.449+0000] {logging_mixin.py:137} INFO - [2023-04-26T23:48:51.439+0000] {dagbag.py:343} ERROR - Failed to import: /opt/airflow/dags/noaa.py
Traceback (most recent call last):
  File "/home/airflow/.local/lib/python3.7/site-packages/airflow/models/dagbag.py", line 339, in parse
    loader.exec_module(new_module)
  File "<frozen importlib._bootstrap_external>", line 724, in exec_module
  File "<frozen importlib._bootstrap_external>", line 860, in get_code
  File "<frozen importlib._bootstrap_external>", line 791, in source_to_code
  File "<frozen importlib._bootstrap>", line 219, in _call_with_frames_removed
  File "/opt/airflow/dags/noaa.py", line 70
    ge_data_context_root_dir_with_checkpoint_name_pass = GreatExpectationsOperator(
    ^
IndentationError: unexpected indent
[2023-04-26T23:48:51.451+0000] {processor.py:755} WARNING - No viable dags retrieved from /opt/airflow/dags/noaa.py
[2023-04-26T23:48:51.489+0000] {processor.py:175} INFO - Processing /opt/airflow/dags/noaa.py took 0.070 seconds
[2023-04-26T23:49:08.550+0000] {processor.py:153} INFO - Started process (PID=555) to work on /opt/airflow/dags/noaa.py
[2023-04-26T23:49:08.551+0000] {processor.py:743} INFO - Processing file /opt/airflow/dags/noaa.py for tasks to queue
[2023-04-26T23:49:08.552+0000] {logging_mixin.py:137} INFO - [2023-04-26T23:49:08.552+0000] {dagbag.py:538} INFO - Filling up the DagBag from /opt/airflow/dags/noaa.py
[2023-04-26T23:49:08.555+0000] {logging_mixin.py:137} INFO - [2023-04-26T23:49:08.554+0000] {dagbag.py:343} ERROR - Failed to import: /opt/airflow/dags/noaa.py
Traceback (most recent call last):
  File "/home/airflow/.local/lib/python3.7/site-packages/airflow/models/dagbag.py", line 339, in parse
    loader.exec_module(new_module)
  File "<frozen importlib._bootstrap_external>", line 724, in exec_module
  File "<frozen importlib._bootstrap_external>", line 860, in get_code
  File "<frozen importlib._bootstrap_external>", line 791, in source_to_code
  File "<frozen importlib._bootstrap>", line 219, in _call_with_frames_removed
  File "/opt/airflow/dags/noaa.py", line 70
    ge_data_context_root_dir_with_checkpoint_name_pass = GreatExpectationsOperator(
    ^
IndentationError: unexpected indent
[2023-04-26T23:49:08.556+0000] {processor.py:755} WARNING - No viable dags retrieved from /opt/airflow/dags/noaa.py
[2023-04-26T23:49:08.574+0000] {processor.py:175} INFO - Processing /opt/airflow/dags/noaa.py took 0.027 seconds
[2023-04-26T23:49:25.787+0000] {processor.py:153} INFO - Started process (PID=566) to work on /opt/airflow/dags/noaa.py
[2023-04-26T23:49:25.858+0000] {processor.py:743} INFO - Processing file /opt/airflow/dags/noaa.py for tasks to queue
[2023-04-26T23:49:25.860+0000] {logging_mixin.py:137} INFO - [2023-04-26T23:49:25.860+0000] {dagbag.py:538} INFO - Filling up the DagBag from /opt/airflow/dags/noaa.py
[2023-04-26T23:49:25.965+0000] {logging_mixin.py:137} INFO - [2023-04-26T23:49:25.863+0000] {dagbag.py:343} ERROR - Failed to import: /opt/airflow/dags/noaa.py
Traceback (most recent call last):
  File "/home/airflow/.local/lib/python3.7/site-packages/airflow/models/dagbag.py", line 339, in parse
    loader.exec_module(new_module)
  File "<frozen importlib._bootstrap_external>", line 724, in exec_module
  File "<frozen importlib._bootstrap_external>", line 860, in get_code
  File "<frozen importlib._bootstrap_external>", line 791, in source_to_code
  File "<frozen importlib._bootstrap>", line 219, in _call_with_frames_removed
  File "/opt/airflow/dags/noaa.py", line 79
    sandbox
    ^
IndentationError: unexpected indent
[2023-04-26T23:49:25.966+0000] {processor.py:755} WARNING - No viable dags retrieved from /opt/airflow/dags/noaa.py
[2023-04-26T23:49:26.159+0000] {processor.py:175} INFO - Processing /opt/airflow/dags/noaa.py took 0.377 seconds
[2023-04-26T23:49:56.378+0000] {processor.py:153} INFO - Started process (PID=596) to work on /opt/airflow/dags/noaa.py
[2023-04-26T23:49:56.380+0000] {processor.py:743} INFO - Processing file /opt/airflow/dags/noaa.py for tasks to queue
[2023-04-26T23:49:56.380+0000] {logging_mixin.py:137} INFO - [2023-04-26T23:49:56.380+0000] {dagbag.py:538} INFO - Filling up the DagBag from /opt/airflow/dags/noaa.py
[2023-04-26T23:49:56.383+0000] {logging_mixin.py:137} INFO - [2023-04-26T23:49:56.382+0000] {dagbag.py:343} ERROR - Failed to import: /opt/airflow/dags/noaa.py
Traceback (most recent call last):
  File "/home/airflow/.local/lib/python3.7/site-packages/airflow/models/dagbag.py", line 339, in parse
    loader.exec_module(new_module)
  File "<frozen importlib._bootstrap_external>", line 724, in exec_module
  File "<frozen importlib._bootstrap_external>", line 860, in get_code
  File "<frozen importlib._bootstrap_external>", line 791, in source_to_code
  File "<frozen importlib._bootstrap>", line 219, in _call_with_frames_removed
  File "/opt/airflow/dags/noaa.py", line 79
    sandbox
    ^
IndentationError: unexpected indent
[2023-04-26T23:49:56.384+0000] {processor.py:755} WARNING - No viable dags retrieved from /opt/airflow/dags/noaa.py
[2023-04-26T23:49:56.407+0000] {processor.py:175} INFO - Processing /opt/airflow/dags/noaa.py took 0.032 seconds
[2023-04-26T23:50:26.575+0000] {processor.py:153} INFO - Started process (PID=617) to work on /opt/airflow/dags/noaa.py
[2023-04-26T23:50:26.576+0000] {processor.py:743} INFO - Processing file /opt/airflow/dags/noaa.py for tasks to queue
[2023-04-26T23:50:26.577+0000] {logging_mixin.py:137} INFO - [2023-04-26T23:50:26.577+0000] {dagbag.py:538} INFO - Filling up the DagBag from /opt/airflow/dags/noaa.py
[2023-04-26T23:50:26.583+0000] {logging_mixin.py:137} INFO - [2023-04-26T23:50:26.580+0000] {dagbag.py:343} ERROR - Failed to import: /opt/airflow/dags/noaa.py
Traceback (most recent call last):
  File "/home/airflow/.local/lib/python3.7/site-packages/airflow/models/dagbag.py", line 339, in parse
    loader.exec_module(new_module)
  File "<frozen importlib._bootstrap_external>", line 724, in exec_module
  File "<frozen importlib._bootstrap_external>", line 860, in get_code
  File "<frozen importlib._bootstrap_external>", line 791, in source_to_code
  File "<frozen importlib._bootstrap>", line 219, in _call_with_frames_removed
  File "/opt/airflow/dags/noaa.py", line 79
    sandbox
    ^
IndentationError: unexpected indent
[2023-04-26T23:50:26.584+0000] {processor.py:755} WARNING - No viable dags retrieved from /opt/airflow/dags/noaa.py
[2023-04-26T23:50:26.606+0000] {processor.py:175} INFO - Processing /opt/airflow/dags/noaa.py took 0.038 seconds
[2023-04-26T23:50:56.797+0000] {processor.py:153} INFO - Started process (PID=649) to work on /opt/airflow/dags/noaa.py
[2023-04-26T23:50:56.813+0000] {processor.py:743} INFO - Processing file /opt/airflow/dags/noaa.py for tasks to queue
[2023-04-26T23:50:56.814+0000] {logging_mixin.py:137} INFO - [2023-04-26T23:50:56.813+0000] {dagbag.py:538} INFO - Filling up the DagBag from /opt/airflow/dags/noaa.py
[2023-04-26T23:50:56.817+0000] {logging_mixin.py:137} INFO - [2023-04-26T23:50:56.815+0000] {dagbag.py:343} ERROR - Failed to import: /opt/airflow/dags/noaa.py
Traceback (most recent call last):
  File "/home/airflow/.local/lib/python3.7/site-packages/airflow/models/dagbag.py", line 339, in parse
    loader.exec_module(new_module)
  File "<frozen importlib._bootstrap_external>", line 724, in exec_module
  File "<frozen importlib._bootstrap_external>", line 860, in get_code
  File "<frozen importlib._bootstrap_external>", line 791, in source_to_code
  File "<frozen importlib._bootstrap>", line 219, in _call_with_frames_removed
  File "/opt/airflow/dags/noaa.py", line 79
    sandbox
    ^
IndentationError: unexpected indent
[2023-04-26T23:50:56.817+0000] {processor.py:755} WARNING - No viable dags retrieved from /opt/airflow/dags/noaa.py
[2023-04-26T23:50:56.872+0000] {processor.py:175} INFO - Processing /opt/airflow/dags/noaa.py took 0.089 seconds
[2023-04-26T23:51:27.098+0000] {processor.py:153} INFO - Started process (PID=671) to work on /opt/airflow/dags/noaa.py
[2023-04-26T23:51:27.104+0000] {processor.py:743} INFO - Processing file /opt/airflow/dags/noaa.py for tasks to queue
[2023-04-26T23:51:27.111+0000] {logging_mixin.py:137} INFO - [2023-04-26T23:51:27.110+0000] {dagbag.py:538} INFO - Filling up the DagBag from /opt/airflow/dags/noaa.py
[2023-04-26T23:51:27.125+0000] {logging_mixin.py:137} INFO - [2023-04-26T23:51:27.121+0000] {dagbag.py:343} ERROR - Failed to import: /opt/airflow/dags/noaa.py
Traceback (most recent call last):
  File "/home/airflow/.local/lib/python3.7/site-packages/airflow/models/dagbag.py", line 339, in parse
    loader.exec_module(new_module)
  File "<frozen importlib._bootstrap_external>", line 724, in exec_module
  File "<frozen importlib._bootstrap_external>", line 860, in get_code
  File "<frozen importlib._bootstrap_external>", line 791, in source_to_code
  File "<frozen importlib._bootstrap>", line 219, in _call_with_frames_removed
  File "/opt/airflow/dags/noaa.py", line 79
    sandbox
    ^
IndentationError: unexpected indent
[2023-04-26T23:51:27.126+0000] {processor.py:755} WARNING - No viable dags retrieved from /opt/airflow/dags/noaa.py
[2023-04-26T23:51:27.156+0000] {processor.py:175} INFO - Processing /opt/airflow/dags/noaa.py took 0.064 seconds
[2023-04-26T23:51:57.314+0000] {processor.py:153} INFO - Started process (PID=692) to work on /opt/airflow/dags/noaa.py
[2023-04-26T23:51:57.317+0000] {processor.py:743} INFO - Processing file /opt/airflow/dags/noaa.py for tasks to queue
[2023-04-26T23:51:57.318+0000] {logging_mixin.py:137} INFO - [2023-04-26T23:51:57.318+0000] {dagbag.py:538} INFO - Filling up the DagBag from /opt/airflow/dags/noaa.py
[2023-04-26T23:51:57.323+0000] {logging_mixin.py:137} INFO - [2023-04-26T23:51:57.321+0000] {dagbag.py:343} ERROR - Failed to import: /opt/airflow/dags/noaa.py
Traceback (most recent call last):
  File "/home/airflow/.local/lib/python3.7/site-packages/airflow/models/dagbag.py", line 339, in parse
    loader.exec_module(new_module)
  File "<frozen importlib._bootstrap_external>", line 724, in exec_module
  File "<frozen importlib._bootstrap_external>", line 860, in get_code
  File "<frozen importlib._bootstrap_external>", line 791, in source_to_code
  File "<frozen importlib._bootstrap>", line 219, in _call_with_frames_removed
  File "/opt/airflow/dags/noaa.py", line 79
    sandbox
    ^
IndentationError: unexpected indent
[2023-04-26T23:51:57.324+0000] {processor.py:755} WARNING - No viable dags retrieved from /opt/airflow/dags/noaa.py
[2023-04-26T23:51:57.351+0000] {processor.py:175} INFO - Processing /opt/airflow/dags/noaa.py took 0.041 seconds
[2023-04-26T23:52:27.523+0000] {processor.py:153} INFO - Started process (PID=722) to work on /opt/airflow/dags/noaa.py
[2023-04-26T23:52:27.524+0000] {processor.py:743} INFO - Processing file /opt/airflow/dags/noaa.py for tasks to queue
[2023-04-26T23:52:27.525+0000] {logging_mixin.py:137} INFO - [2023-04-26T23:52:27.524+0000] {dagbag.py:538} INFO - Filling up the DagBag from /opt/airflow/dags/noaa.py
[2023-04-26T23:52:27.527+0000] {logging_mixin.py:137} INFO - [2023-04-26T23:52:27.526+0000] {dagbag.py:343} ERROR - Failed to import: /opt/airflow/dags/noaa.py
Traceback (most recent call last):
  File "/home/airflow/.local/lib/python3.7/site-packages/airflow/models/dagbag.py", line 339, in parse
    loader.exec_module(new_module)
  File "<frozen importlib._bootstrap_external>", line 724, in exec_module
  File "<frozen importlib._bootstrap_external>", line 860, in get_code
  File "<frozen importlib._bootstrap_external>", line 791, in source_to_code
  File "<frozen importlib._bootstrap>", line 219, in _call_with_frames_removed
  File "/opt/airflow/dags/noaa.py", line 79
    sandbox
    ^
IndentationError: unexpected indent
[2023-04-26T23:52:27.527+0000] {processor.py:755} WARNING - No viable dags retrieved from /opt/airflow/dags/noaa.py
[2023-04-26T23:52:27.554+0000] {processor.py:175} INFO - Processing /opt/airflow/dags/noaa.py took 0.036 seconds
[2023-04-26T23:52:57.729+0000] {processor.py:153} INFO - Started process (PID=743) to work on /opt/airflow/dags/noaa.py
[2023-04-26T23:52:57.731+0000] {processor.py:743} INFO - Processing file /opt/airflow/dags/noaa.py for tasks to queue
[2023-04-26T23:52:57.732+0000] {logging_mixin.py:137} INFO - [2023-04-26T23:52:57.731+0000] {dagbag.py:538} INFO - Filling up the DagBag from /opt/airflow/dags/noaa.py
[2023-04-26T23:52:57.734+0000] {logging_mixin.py:137} INFO - [2023-04-26T23:52:57.733+0000] {dagbag.py:343} ERROR - Failed to import: /opt/airflow/dags/noaa.py
Traceback (most recent call last):
  File "/home/airflow/.local/lib/python3.7/site-packages/airflow/models/dagbag.py", line 339, in parse
    loader.exec_module(new_module)
  File "<frozen importlib._bootstrap_external>", line 724, in exec_module
  File "<frozen importlib._bootstrap_external>", line 860, in get_code
  File "<frozen importlib._bootstrap_external>", line 791, in source_to_code
  File "<frozen importlib._bootstrap>", line 219, in _call_with_frames_removed
  File "/opt/airflow/dags/noaa.py", line 79
    sandbox
    ^
IndentationError: unexpected indent
[2023-04-26T23:52:57.734+0000] {processor.py:755} WARNING - No viable dags retrieved from /opt/airflow/dags/noaa.py
[2023-04-26T23:52:57.758+0000] {processor.py:175} INFO - Processing /opt/airflow/dags/noaa.py took 0.033 seconds
[2023-04-26T23:53:27.955+0000] {processor.py:153} INFO - Started process (PID=774) to work on /opt/airflow/dags/noaa.py
[2023-04-26T23:53:27.956+0000] {processor.py:743} INFO - Processing file /opt/airflow/dags/noaa.py for tasks to queue
[2023-04-26T23:53:27.957+0000] {logging_mixin.py:137} INFO - [2023-04-26T23:53:27.957+0000] {dagbag.py:538} INFO - Filling up the DagBag from /opt/airflow/dags/noaa.py
[2023-04-26T23:53:27.961+0000] {logging_mixin.py:137} INFO - [2023-04-26T23:53:27.959+0000] {dagbag.py:343} ERROR - Failed to import: /opt/airflow/dags/noaa.py
Traceback (most recent call last):
  File "/home/airflow/.local/lib/python3.7/site-packages/airflow/models/dagbag.py", line 339, in parse
    loader.exec_module(new_module)
  File "<frozen importlib._bootstrap_external>", line 724, in exec_module
  File "<frozen importlib._bootstrap_external>", line 860, in get_code
  File "<frozen importlib._bootstrap_external>", line 791, in source_to_code
  File "<frozen importlib._bootstrap>", line 219, in _call_with_frames_removed
  File "/opt/airflow/dags/noaa.py", line 79
    sandbox
    ^
IndentationError: unexpected indent
[2023-04-26T23:53:27.961+0000] {processor.py:755} WARNING - No viable dags retrieved from /opt/airflow/dags/noaa.py
[2023-04-26T23:53:27.985+0000] {processor.py:175} INFO - Processing /opt/airflow/dags/noaa.py took 0.034 seconds
[2023-04-26T23:53:58.149+0000] {processor.py:153} INFO - Started process (PID=795) to work on /opt/airflow/dags/noaa.py
[2023-04-26T23:53:58.151+0000] {processor.py:743} INFO - Processing file /opt/airflow/dags/noaa.py for tasks to queue
[2023-04-26T23:53:58.152+0000] {logging_mixin.py:137} INFO - [2023-04-26T23:53:58.152+0000] {dagbag.py:538} INFO - Filling up the DagBag from /opt/airflow/dags/noaa.py
[2023-04-26T23:53:58.155+0000] {logging_mixin.py:137} INFO - [2023-04-26T23:53:58.153+0000] {dagbag.py:343} ERROR - Failed to import: /opt/airflow/dags/noaa.py
Traceback (most recent call last):
  File "/home/airflow/.local/lib/python3.7/site-packages/airflow/models/dagbag.py", line 339, in parse
    loader.exec_module(new_module)
  File "<frozen importlib._bootstrap_external>", line 724, in exec_module
  File "<frozen importlib._bootstrap_external>", line 860, in get_code
  File "<frozen importlib._bootstrap_external>", line 791, in source_to_code
  File "<frozen importlib._bootstrap>", line 219, in _call_with_frames_removed
  File "/opt/airflow/dags/noaa.py", line 79
    sandbox
    ^
IndentationError: unexpected indent
[2023-04-26T23:53:58.155+0000] {processor.py:755} WARNING - No viable dags retrieved from /opt/airflow/dags/noaa.py
[2023-04-26T23:53:58.219+0000] {processor.py:175} INFO - Processing /opt/airflow/dags/noaa.py took 0.073 seconds
[2023-04-26T23:54:28.360+0000] {processor.py:153} INFO - Started process (PID=816) to work on /opt/airflow/dags/noaa.py
[2023-04-26T23:54:28.361+0000] {processor.py:743} INFO - Processing file /opt/airflow/dags/noaa.py for tasks to queue
[2023-04-26T23:54:28.362+0000] {logging_mixin.py:137} INFO - [2023-04-26T23:54:28.362+0000] {dagbag.py:538} INFO - Filling up the DagBag from /opt/airflow/dags/noaa.py
[2023-04-26T23:54:28.367+0000] {logging_mixin.py:137} INFO - [2023-04-26T23:54:28.365+0000] {dagbag.py:343} ERROR - Failed to import: /opt/airflow/dags/noaa.py
Traceback (most recent call last):
  File "/home/airflow/.local/lib/python3.7/site-packages/airflow/models/dagbag.py", line 339, in parse
    loader.exec_module(new_module)
  File "<frozen importlib._bootstrap_external>", line 724, in exec_module
  File "<frozen importlib._bootstrap_external>", line 860, in get_code
  File "<frozen importlib._bootstrap_external>", line 791, in source_to_code
  File "<frozen importlib._bootstrap>", line 219, in _call_with_frames_removed
  File "/opt/airflow/dags/noaa.py", line 79
    sandbox
    ^
IndentationError: unexpected indent
[2023-04-26T23:54:28.368+0000] {processor.py:755} WARNING - No viable dags retrieved from /opt/airflow/dags/noaa.py
[2023-04-26T23:54:28.396+0000] {processor.py:175} INFO - Processing /opt/airflow/dags/noaa.py took 0.039 seconds
[2023-04-26T23:54:58.598+0000] {processor.py:153} INFO - Started process (PID=848) to work on /opt/airflow/dags/noaa.py
[2023-04-26T23:54:58.600+0000] {processor.py:743} INFO - Processing file /opt/airflow/dags/noaa.py for tasks to queue
[2023-04-26T23:54:58.600+0000] {logging_mixin.py:137} INFO - [2023-04-26T23:54:58.600+0000] {dagbag.py:538} INFO - Filling up the DagBag from /opt/airflow/dags/noaa.py
[2023-04-26T23:54:58.603+0000] {logging_mixin.py:137} INFO - [2023-04-26T23:54:58.601+0000] {dagbag.py:343} ERROR - Failed to import: /opt/airflow/dags/noaa.py
Traceback (most recent call last):
  File "/home/airflow/.local/lib/python3.7/site-packages/airflow/models/dagbag.py", line 339, in parse
    loader.exec_module(new_module)
  File "<frozen importlib._bootstrap_external>", line 724, in exec_module
  File "<frozen importlib._bootstrap_external>", line 860, in get_code
  File "<frozen importlib._bootstrap_external>", line 791, in source_to_code
  File "<frozen importlib._bootstrap>", line 219, in _call_with_frames_removed
  File "/opt/airflow/dags/noaa.py", line 79
    sandbox
    ^
IndentationError: unexpected indent
[2023-04-26T23:54:58.604+0000] {processor.py:755} WARNING - No viable dags retrieved from /opt/airflow/dags/noaa.py
[2023-04-26T23:54:58.631+0000] {processor.py:175} INFO - Processing /opt/airflow/dags/noaa.py took 0.036 seconds
[2023-04-26T23:55:33.393+0000] {processor.py:153} INFO - Started process (PID=849) to work on /opt/airflow/dags/noaa.py
[2023-04-26T23:55:33.394+0000] {processor.py:743} INFO - Processing file /opt/airflow/dags/noaa.py for tasks to queue
[2023-04-26T23:55:33.395+0000] {logging_mixin.py:137} INFO - [2023-04-26T23:55:33.395+0000] {dagbag.py:538} INFO - Filling up the DagBag from /opt/airflow/dags/noaa.py
[2023-04-26T23:55:33.409+0000] {logging_mixin.py:137} INFO - [2023-04-26T23:55:33.399+0000] {dagbag.py:343} ERROR - Failed to import: /opt/airflow/dags/noaa.py
Traceback (most recent call last):
  File "/home/airflow/.local/lib/python3.7/site-packages/airflow/models/dagbag.py", line 339, in parse
    loader.exec_module(new_module)
  File "<frozen importlib._bootstrap_external>", line 724, in exec_module
  File "<frozen importlib._bootstrap_external>", line 860, in get_code
  File "<frozen importlib._bootstrap_external>", line 791, in source_to_code
  File "<frozen importlib._bootstrap>", line 219, in _call_with_frames_removed
  File "/opt/airflow/dags/noaa.py", line 79
    sandbox
    ^
IndentationError: unexpected indent
[2023-04-26T23:55:33.409+0000] {processor.py:755} WARNING - No viable dags retrieved from /opt/airflow/dags/noaa.py
[2023-04-26T23:55:33.434+0000] {processor.py:175} INFO - Processing /opt/airflow/dags/noaa.py took 0.044 seconds
[2023-04-26T23:56:03.572+0000] {processor.py:153} INFO - Started process (PID=880) to work on /opt/airflow/dags/noaa.py
[2023-04-26T23:56:03.574+0000] {processor.py:743} INFO - Processing file /opt/airflow/dags/noaa.py for tasks to queue
[2023-04-26T23:56:03.574+0000] {logging_mixin.py:137} INFO - [2023-04-26T23:56:03.574+0000] {dagbag.py:538} INFO - Filling up the DagBag from /opt/airflow/dags/noaa.py
[2023-04-26T23:56:03.577+0000] {logging_mixin.py:137} INFO - [2023-04-26T23:56:03.576+0000] {dagbag.py:343} ERROR - Failed to import: /opt/airflow/dags/noaa.py
Traceback (most recent call last):
  File "/home/airflow/.local/lib/python3.7/site-packages/airflow/models/dagbag.py", line 339, in parse
    loader.exec_module(new_module)
  File "<frozen importlib._bootstrap_external>", line 724, in exec_module
  File "<frozen importlib._bootstrap_external>", line 860, in get_code
  File "<frozen importlib._bootstrap_external>", line 791, in source_to_code
  File "<frozen importlib._bootstrap>", line 219, in _call_with_frames_removed
  File "/opt/airflow/dags/noaa.py", line 79
    sandbox
    ^
IndentationError: unexpected indent
[2023-04-26T23:56:03.577+0000] {processor.py:755} WARNING - No viable dags retrieved from /opt/airflow/dags/noaa.py
[2023-04-26T23:56:03.616+0000] {processor.py:175} INFO - Processing /opt/airflow/dags/noaa.py took 0.052 seconds
[2023-04-26T23:56:33.824+0000] {processor.py:153} INFO - Started process (PID=901) to work on /opt/airflow/dags/noaa.py
[2023-04-26T23:56:33.825+0000] {processor.py:743} INFO - Processing file /opt/airflow/dags/noaa.py for tasks to queue
[2023-04-26T23:56:33.826+0000] {logging_mixin.py:137} INFO - [2023-04-26T23:56:33.826+0000] {dagbag.py:538} INFO - Filling up the DagBag from /opt/airflow/dags/noaa.py
[2023-04-26T23:56:33.828+0000] {logging_mixin.py:137} INFO - [2023-04-26T23:56:33.827+0000] {dagbag.py:343} ERROR - Failed to import: /opt/airflow/dags/noaa.py
Traceback (most recent call last):
  File "/home/airflow/.local/lib/python3.7/site-packages/airflow/models/dagbag.py", line 339, in parse
    loader.exec_module(new_module)
  File "<frozen importlib._bootstrap_external>", line 724, in exec_module
  File "<frozen importlib._bootstrap_external>", line 860, in get_code
  File "<frozen importlib._bootstrap_external>", line 791, in source_to_code
  File "<frozen importlib._bootstrap>", line 219, in _call_with_frames_removed
  File "/opt/airflow/dags/noaa.py", line 79
    sandbox
    ^
IndentationError: unexpected indent
[2023-04-26T23:56:33.829+0000] {processor.py:755} WARNING - No viable dags retrieved from /opt/airflow/dags/noaa.py
[2023-04-26T23:56:33.849+0000] {processor.py:175} INFO - Processing /opt/airflow/dags/noaa.py took 0.028 seconds
[2023-04-26T23:57:04.003+0000] {processor.py:153} INFO - Started process (PID=932) to work on /opt/airflow/dags/noaa.py
[2023-04-26T23:57:04.005+0000] {processor.py:743} INFO - Processing file /opt/airflow/dags/noaa.py for tasks to queue
[2023-04-26T23:57:04.005+0000] {logging_mixin.py:137} INFO - [2023-04-26T23:57:04.005+0000] {dagbag.py:538} INFO - Filling up the DagBag from /opt/airflow/dags/noaa.py
[2023-04-26T23:57:04.007+0000] {logging_mixin.py:137} INFO - [2023-04-26T23:57:04.007+0000] {dagbag.py:343} ERROR - Failed to import: /opt/airflow/dags/noaa.py
Traceback (most recent call last):
  File "/home/airflow/.local/lib/python3.7/site-packages/airflow/models/dagbag.py", line 339, in parse
    loader.exec_module(new_module)
  File "<frozen importlib._bootstrap_external>", line 724, in exec_module
  File "<frozen importlib._bootstrap_external>", line 860, in get_code
  File "<frozen importlib._bootstrap_external>", line 791, in source_to_code
  File "<frozen importlib._bootstrap>", line 219, in _call_with_frames_removed
  File "/opt/airflow/dags/noaa.py", line 79
    sandbox
    ^
IndentationError: unexpected indent
[2023-04-26T23:57:04.007+0000] {processor.py:755} WARNING - No viable dags retrieved from /opt/airflow/dags/noaa.py
[2023-04-26T23:57:04.027+0000] {processor.py:175} INFO - Processing /opt/airflow/dags/noaa.py took 0.026 seconds
[2023-04-26T23:57:34.173+0000] {processor.py:153} INFO - Started process (PID=955) to work on /opt/airflow/dags/noaa.py
[2023-04-26T23:57:34.175+0000] {processor.py:743} INFO - Processing file /opt/airflow/dags/noaa.py for tasks to queue
[2023-04-26T23:57:34.176+0000] {logging_mixin.py:137} INFO - [2023-04-26T23:57:34.176+0000] {dagbag.py:538} INFO - Filling up the DagBag from /opt/airflow/dags/noaa.py
[2023-04-26T23:57:34.178+0000] {logging_mixin.py:137} INFO - [2023-04-26T23:57:34.177+0000] {dagbag.py:343} ERROR - Failed to import: /opt/airflow/dags/noaa.py
Traceback (most recent call last):
  File "/home/airflow/.local/lib/python3.7/site-packages/airflow/models/dagbag.py", line 339, in parse
    loader.exec_module(new_module)
  File "<frozen importlib._bootstrap_external>", line 724, in exec_module
  File "<frozen importlib._bootstrap_external>", line 860, in get_code
  File "<frozen importlib._bootstrap_external>", line 791, in source_to_code
  File "<frozen importlib._bootstrap>", line 219, in _call_with_frames_removed
  File "/opt/airflow/dags/noaa.py", line 79
    sandbox
    ^
IndentationError: unexpected indent
[2023-04-26T23:57:34.178+0000] {processor.py:755} WARNING - No viable dags retrieved from /opt/airflow/dags/noaa.py
[2023-04-26T23:57:34.197+0000] {processor.py:175} INFO - Processing /opt/airflow/dags/noaa.py took 0.027 seconds
[2023-04-26T23:58:04.361+0000] {processor.py:153} INFO - Started process (PID=986) to work on /opt/airflow/dags/noaa.py
[2023-04-26T23:58:04.362+0000] {processor.py:743} INFO - Processing file /opt/airflow/dags/noaa.py for tasks to queue
[2023-04-26T23:58:04.363+0000] {logging_mixin.py:137} INFO - [2023-04-26T23:58:04.363+0000] {dagbag.py:538} INFO - Filling up the DagBag from /opt/airflow/dags/noaa.py
[2023-04-26T23:58:04.365+0000] {logging_mixin.py:137} INFO - [2023-04-26T23:58:04.364+0000] {dagbag.py:343} ERROR - Failed to import: /opt/airflow/dags/noaa.py
Traceback (most recent call last):
  File "/home/airflow/.local/lib/python3.7/site-packages/airflow/models/dagbag.py", line 339, in parse
    loader.exec_module(new_module)
  File "<frozen importlib._bootstrap_external>", line 724, in exec_module
  File "<frozen importlib._bootstrap_external>", line 860, in get_code
  File "<frozen importlib._bootstrap_external>", line 791, in source_to_code
  File "<frozen importlib._bootstrap>", line 219, in _call_with_frames_removed
  File "/opt/airflow/dags/noaa.py", line 79
    sandbox
    ^
IndentationError: unexpected indent
[2023-04-26T23:58:04.365+0000] {processor.py:755} WARNING - No viable dags retrieved from /opt/airflow/dags/noaa.py
[2023-04-26T23:58:04.382+0000] {processor.py:175} INFO - Processing /opt/airflow/dags/noaa.py took 0.023 seconds
[2023-04-26T23:58:34.594+0000] {processor.py:153} INFO - Started process (PID=1008) to work on /opt/airflow/dags/noaa.py
[2023-04-26T23:58:34.609+0000] {processor.py:743} INFO - Processing file /opt/airflow/dags/noaa.py for tasks to queue
[2023-04-26T23:58:34.609+0000] {logging_mixin.py:137} INFO - [2023-04-26T23:58:34.609+0000] {dagbag.py:538} INFO - Filling up the DagBag from /opt/airflow/dags/noaa.py
[2023-04-26T23:58:34.632+0000] {logging_mixin.py:137} INFO - [2023-04-26T23:58:34.611+0000] {dagbag.py:343} ERROR - Failed to import: /opt/airflow/dags/noaa.py
Traceback (most recent call last):
  File "/home/airflow/.local/lib/python3.7/site-packages/airflow/models/dagbag.py", line 339, in parse
    loader.exec_module(new_module)
  File "<frozen importlib._bootstrap_external>", line 724, in exec_module
  File "<frozen importlib._bootstrap_external>", line 860, in get_code
  File "<frozen importlib._bootstrap_external>", line 791, in source_to_code
  File "<frozen importlib._bootstrap>", line 219, in _call_with_frames_removed
  File "/opt/airflow/dags/noaa.py", line 79
    sandbox
    ^
IndentationError: unexpected indent
[2023-04-26T23:58:34.632+0000] {processor.py:755} WARNING - No viable dags retrieved from /opt/airflow/dags/noaa.py
[2023-04-26T23:58:34.895+0000] {processor.py:175} INFO - Processing /opt/airflow/dags/noaa.py took 0.303 seconds
[2023-04-26T23:59:05.063+0000] {processor.py:153} INFO - Started process (PID=1039) to work on /opt/airflow/dags/noaa.py
[2023-04-26T23:59:05.066+0000] {processor.py:743} INFO - Processing file /opt/airflow/dags/noaa.py for tasks to queue
[2023-04-26T23:59:05.067+0000] {logging_mixin.py:137} INFO - [2023-04-26T23:59:05.067+0000] {dagbag.py:538} INFO - Filling up the DagBag from /opt/airflow/dags/noaa.py
[2023-04-26T23:59:05.069+0000] {logging_mixin.py:137} INFO - [2023-04-26T23:59:05.068+0000] {dagbag.py:343} ERROR - Failed to import: /opt/airflow/dags/noaa.py
Traceback (most recent call last):
  File "/home/airflow/.local/lib/python3.7/site-packages/airflow/models/dagbag.py", line 339, in parse
    loader.exec_module(new_module)
  File "<frozen importlib._bootstrap_external>", line 724, in exec_module
  File "<frozen importlib._bootstrap_external>", line 860, in get_code
  File "<frozen importlib._bootstrap_external>", line 791, in source_to_code
  File "<frozen importlib._bootstrap>", line 219, in _call_with_frames_removed
  File "/opt/airflow/dags/noaa.py", line 79
    sandbox
    ^
IndentationError: unexpected indent
[2023-04-26T23:59:05.069+0000] {processor.py:755} WARNING - No viable dags retrieved from /opt/airflow/dags/noaa.py
[2023-04-26T23:59:05.098+0000] {processor.py:175} INFO - Processing /opt/airflow/dags/noaa.py took 0.039 seconds
[2023-04-26T23:59:35.272+0000] {processor.py:153} INFO - Started process (PID=1060) to work on /opt/airflow/dags/noaa.py
[2023-04-26T23:59:35.273+0000] {processor.py:743} INFO - Processing file /opt/airflow/dags/noaa.py for tasks to queue
[2023-04-26T23:59:35.274+0000] {logging_mixin.py:137} INFO - [2023-04-26T23:59:35.274+0000] {dagbag.py:538} INFO - Filling up the DagBag from /opt/airflow/dags/noaa.py
[2023-04-26T23:59:35.276+0000] {logging_mixin.py:137} INFO - [2023-04-26T23:59:35.275+0000] {dagbag.py:343} ERROR - Failed to import: /opt/airflow/dags/noaa.py
Traceback (most recent call last):
  File "/home/airflow/.local/lib/python3.7/site-packages/airflow/models/dagbag.py", line 339, in parse
    loader.exec_module(new_module)
  File "<frozen importlib._bootstrap_external>", line 724, in exec_module
  File "<frozen importlib._bootstrap_external>", line 860, in get_code
  File "<frozen importlib._bootstrap_external>", line 791, in source_to_code
  File "<frozen importlib._bootstrap>", line 219, in _call_with_frames_removed
  File "/opt/airflow/dags/noaa.py", line 79
    sandbox
    ^
IndentationError: unexpected indent
[2023-04-26T23:59:35.276+0000] {processor.py:755} WARNING - No viable dags retrieved from /opt/airflow/dags/noaa.py
[2023-04-26T23:59:35.293+0000] {processor.py:175} INFO - Processing /opt/airflow/dags/noaa.py took 0.025 seconds
